Workbook

Sheet STATUS
B2: ET part number | C2: p000566
B4: PPAP Number | C4: PPAP Req'd by Customer | D4: Current Status | E4: PPAP/IMDS from | F4: CUSTOMER | G4: Country | H4: Customer PN | I4: ET Model | J4: Manufacturer | K4: ET Dwg | L4: Rev | M4: ET PN | N4: Description | O4: IMDS number | P4: IMDS Status | Q4: PPAP docs | R4: Run@Rate | S4: Packing spec | T4: Feasibility report | U4: Level | V4: PPAP samples status | W4: Reason of Submission | X4: Sent to Customer | Y4: PSW returned from Cust Signed
B5: {=IFERROR(INDEX('MASTER LIST'!B:B,SMALL(IF('MASTER LIST'!$N:$N=$C$2,ROW('MASTER LIST'!$N:$N),""),ROWS(B$5:B5))),"")} | C5: {=IFERROR(INDEX('MASTER LIST'!C:C,SMALL(IF('MASTER LIST'!$N:$N=$C$2,ROW('MASTER LIST'!$N:$N),""),ROWS(C$5:C5))),"")} | D5: {=IFERROR(INDEX('MASTER LIST'!D:D,SMALL(IF('MASTER LIST'!$N:$N=$C$2,ROW('MASTER LIST'!$N:$N),""),ROWS(D$5:D5))),"")} | E5: {=IFERROR(INDEX('MASTER LIST'!E:E,SMALL(IF('MASTER LIST'!$N:$N=$C$2,ROW('MASTER LIST'!$N:$N),""),ROWS(E$5:E5))),"")} | F5: {=IFERROR(INDEX('MASTER LIST'!G:G,SMALL(IF('MASTER LIST'!$N:$N=$C$2,ROW('MASTER LIST'!$N:$N),""),ROWS(F$5:F5))),"")} | G5: {=IFERROR(INDEX('MASTER LIST'!H:H,SMALL(IF('MASTER LIST'!$N:$N=$C$2,ROW('MASTER LIST'!$N:$N),""),ROWS(G$5:G5))),"")} | H5: {=IFERROR(INDEX('MASTER LIST'!I:I,SMALL(IF('MASTER LIST'!$N:$N=$C$2,ROW('MASTER LIST'!$N:$N),""),ROWS(H$5:H5))),"")} | I5: {=IFERROR(INDEX('MASTER LIST'!J:J,SMALL(IF('MASTER LIST'!$N:$N=$C$2,ROW('MASTER LIST'!$N:$N),""),ROWS(I$5:I5))),"")} | J5: {=IFERROR(INDEX('MASTER LIST'!K:K,SMALL(IF('MASTER LIST'!$N:$N=$C$2,ROW('MASTER LIST'!$N:$N),""),ROWS(J$5:J5))),"")} | K5: {=IFERROR(INDEX('MASTER LIST'!L:L,SMALL(IF('MASTER LIST'!$N:$N=$C$2,ROW('MASTER LIST'!$N:$N),""),ROWS(K$5:K5))),"")} | L5: {=IFERROR(INDEX('MASTER LIST'!M:M,SMALL(IF('MASTER LIST'!$N:$N=$C$2,ROW('MASTER LIST'!$N:$N),""),ROWS(L$5:L5))),"")} | M5: {=IFERROR(INDEX('MASTER LIST'!N:N,SMALL(IF('MASTER LIST'!$N:$N=$C$2,ROW('MASTER LIST'!$N:$N),""),ROWS(M$5:M5))),"")} | N5: {=IFERROR(INDEX('MASTER LIST'!P:P,SMALL(IF('MASTER LIST'!$N:$N=$C$2,ROW('MASTER LIST'!$N:$N),""),ROWS(N$5:N5))),"")} | O5: {=IFERROR(INDEX('MASTER LIST'!Q:Q,SMALL(IF('MASTER LIST'!$N:$N=$C$2,ROW('MASTER LIST'!$N:$N),""),ROWS(O$5:O5))),"")} | P5: {=IFERROR(INDEX('MASTER LIST'!#REF!,SMALL(IF('MASTER LIST'!$N:$N=$C$2,ROW('MASTER LIST'!$N:$N),""),ROWS(P$5:P5))),"")} | Q5: {=IFERROR(INDEX('MASTER LIST'!R:R,SMALL(IF('MASTER LIST'!$N:$N=$C$2,ROW('MASTER LIST'!$N:$N),""),ROWS(Q$5:Q5))),"")} | R5: {=IFERROR(INDEX('MASTER LIST'!#REF!,SMALL(IF('MASTER LIST'!$N:$N=$C$2,ROW('MASTER LIST'!$N:$N),""),ROWS(R$5:R5))),"")} | S5: {=IFERROR(INDEX('MASTER LIST'!#REF!,SMALL(IF('MASTER LIST'!$N:$N=$C$2,ROW('MASTER LIST'!$N:$N),""),ROWS(S$5:S5))),"")} | T5: {=IFERROR(INDEX('MASTER LIST'!#REF!,SMALL(IF('MASTER LIST'!$N:$N=$C$2,ROW('MASTER LIST'!$N:$N),""),ROWS(T$5:T5))),"")} | U5: {=IFERROR(INDEX('MASTER LIST'!S:S,SMALL(IF('MASTER LIST'!$N:$N=$C$2,ROW('MASTER LIST'!$N:$N),""),ROWS(U$5:U5))),"")} | V5: {=IFERROR(INDEX('MASTER LIST'!T:T,SMALL(IF('MASTER LIST'!$N:$N=$C$2,ROW('MASTER LIST'!$N:$N),""),ROWS(V$5:V5))),"")} | W5: {=IFERROR(INDEX('MASTER LIST'!U:U,SMALL(IF('MASTER LIST'!$N:$N=$C$2,ROW('MASTER LIST'!$N:$N),""),ROWS(W$5:W5))),"")} | X5: {=IFERROR(INDEX('MASTER LIST'!V:V,SMALL(IF('MASTER LIST'!$N:$N=$C$2,ROW('MASTER LIST'!$N:$N),""),ROWS(X$5:X5))),"")} | Y5: {=IFERROR(INDEX('MASTER LIST'!W:W,SMALL(IF('MASTER LIST'!$N:$N=$C$2,ROW('MASTER LIST'!$N:$N),""),ROWS(Y$5:Y5))),"")}
B6: {=IFERROR(INDEX('MASTER LIST'!B:B,SMALL(IF('MASTER LIST'!$N:$N=$C$2,ROW('MASTER LIST'!$N:$N),""),ROWS(B$5:B6))),"")} | C6: {=IFERROR(INDEX('MASTER LIST'!C:C,SMALL(IF('MASTER LIST'!$N:$N=$C$2,ROW('MASTER LIST'!$N:$N),""),ROWS(C$5:C6))),"")} | D6: {=IFERROR(INDEX('MASTER LIST'!D:D,SMALL(IF('MASTER LIST'!$N:$N=$C$2,ROW('MASTER LIST'!$N:$N),""),ROWS(D$5:D6))),"")} | E6: {=IFERROR(INDEX('MASTER LIST'!E:E,SMALL(IF('MASTER LIST'!$N:$N=$C$2,ROW('MASTER LIST'!$N:$N),""),ROWS(E$5:E6))),"")} | F6: {=IFERROR(INDEX('MASTER LIST'!G:G,SMALL(IF('MASTER LIST'!$N:$N=$C$2,ROW('MASTER LIST'!$N:$N),""),ROWS(F$5:F6))),"")} | G6: {=IFERROR(INDEX('MASTER LIST'!H:H,SMALL(IF('MASTER LIST'!$N:$N=$C$2,ROW('MASTER LIST'!$N:$N),""),ROWS(G$5:G6))),"")} | H6: {=IFERROR(INDEX('MASTER LIST'!I:I,SMALL(IF('MASTER LIST'!$N:$N=$C$2,ROW('MASTER LIST'!$N:$N),""),ROWS(H$5:H6))),"")} | I6: {=IFERROR(INDEX('MASTER LIST'!J:J,SMALL(IF('MASTER LIST'!$N:$N=$C$2,ROW('MASTER LIST'!$N:$N),""),ROWS(I$5:I6))),"")} | J6: {=IFERROR(INDEX('MASTER LIST'!K:K,SMALL(IF('MASTER LIST'!$N:$N=$C$2,ROW('MASTER LIST'!$N:$N),""),ROWS(J$5:J6))),"")} | K6: {=IFERROR(INDEX('MASTER LIST'!L:L,SMALL(IF('MASTER LIST'!$N:$N=$C$2,ROW('MASTER LIST'!$N:$N),""),ROWS(K$5:K6))),"")} | L6: {=IFERROR(INDEX('MASTER LIST'!M:M,SMALL(IF('MASTER LIST'!$N:$N=$C$2,ROW('MASTER LIST'!$N:$N),""),ROWS(L$5:L6))),"")} | M6: {=IFERROR(INDEX('MASTER LIST'!N:N,SMALL(IF('MASTER LIST'!$N:$N=$C$2,ROW('MASTER LIST'!$N:$N),""),ROWS(M$5:M6))),"")} | N6: {=IFERROR(INDEX('MASTER LIST'!P:P,SMALL(IF('MASTER LIST'!$N:$N=$C$2,ROW('MASTER LIST'!$N:$N),""),ROWS(N$5:N6))),"")} | O6: {=IFERROR(INDEX('MASTER LIST'!Q:Q,SMALL(IF('MASTER LIST'!$N:$N=$C$2,ROW('MASTER LIST'!$N:$N),""),ROWS(O$5:O6))),"")} | P6: {=IFERROR(INDEX('MASTER LIST'!#REF!,SMALL(IF('MASTER LIST'!$N:$N=$C$2,ROW('MASTER LIST'!$N:$N),""),ROWS(P$5:P6))),"")} | Q6: {=IFERROR(INDEX('MASTER LIST'!R:R,SMALL(IF('MASTER LIST'!$N:$N=$C$2,ROW('MASTER LIST'!$N:$N),""),ROWS(Q$5:Q6))),"")} | R6: {=IFERROR(INDEX('MASTER LIST'!#REF!,SMALL(IF('MASTER LIST'!$N:$N=$C$2,ROW('MASTER LIST'!$N:$N),""),ROWS(R$5:R6))),"")} | S6: {=IFERROR(INDEX('MASTER LIST'!#REF!,SMALL(IF('MASTER LIST'!$N:$N=$C$2,ROW('MASTER LIST'!$N:$N),""),ROWS(S$5:S6))),"")} | T6: {=IFERROR(INDEX('MASTER LIST'!#REF!,SMALL(IF('MASTER LIST'!$N:$N=$C$2,ROW('MASTER LIST'!$N:$N),""),ROWS(T$5:T6))),"")} | U6: {=IFERROR(INDEX('MASTER LIST'!S:S,SMALL(IF('MASTER LIST'!$N:$N=$C$2,ROW('MASTER LIST'!$N:$N),""),ROWS(U$5:U6))),"")} | V6: {=IFERROR(INDEX('MASTER LIST'!T:T,SMALL(IF('MASTER LIST'!$N:$N=$C$2,ROW('MASTER LIST'!$N:$N),""),ROWS(V$5:V6))),"")} | W6: {=IFERROR(INDEX('MASTER LIST'!U:U,SMALL(IF('MASTER LIST'!$N:$N=$C$2,ROW('MASTER LIST'!$N:$N),""),ROWS(W$5:W6))),"")} | X6: {=IFERROR(INDEX('MASTER LIST'!V:V,SMALL(IF('MASTER LIST'!$N:$N=$C$2,ROW('MASTER LIST'!$N:$N),""),ROWS(X$5:X6))),"")} | Y6: {=IFERROR(INDEX('MASTER LIST'!W:W,SMALL(IF('MASTER LIST'!$N:$N=$C$2,ROW('MASTER LIST'!$N:$N),""),ROWS(Y$5:Y6))),"")}
B7: {=IFERROR(INDEX('MASTER LIST'!B:B,SMALL(IF('MASTER LIST'!$N:$N=$C$2,ROW('MASTER LIST'!$N:$N),""),ROWS(B$5:B7))),"")} | C7: {=IFERROR(INDEX('MASTER LIST'!C:C,SMALL(IF('MASTER LIST'!$N:$N=$C$2,ROW('MASTER LIST'!$N:$N),""),ROWS(C$5:C7))),"")} | D7: {=IFERROR(INDEX('MASTER LIST'!D:D,SMALL(IF('MASTER LIST'!$N:$N=$C$2,ROW('MASTER LIST'!$N:$N),""),ROWS(D$5:D7))),"")} | E7: {=IFERROR(INDEX('MASTER LIST'!E:E,SMALL(IF('MASTER LIST'!$N:$N=$C$2,ROW('MASTER LIST'!$N:$N),""),ROWS(E$5:E7))),"")} | F7: {=IFERROR(INDEX('MASTER LIST'!G:G,SMALL(IF('MASTER LIST'!$N:$N=$C$2,ROW('MASTER LIST'!$N:$N),""),ROWS(F$5:F7))),"")} | G7: {=IFERROR(INDEX('MASTER LIST'!H:H,SMALL(IF('MASTER LIST'!$N:$N=$C$2,ROW('MASTER LIST'!$N:$N),""),ROWS(G$5:G7))),"")} | H7: {=IFERROR(INDEX('MASTER LIST'!I:I,SMALL(IF('MASTER LIST'!$N:$N=$C$2,ROW('MASTER LIST'!$N:$N),""),ROWS(H$5:H7))),"")} | I7: {=IFERROR(INDEX('MASTER LIST'!J:J,SMALL(IF('MASTER LIST'!$N:$N=$C$2,ROW('MASTER LIST'!$N:$N),""),ROWS(I$5:I7))),"")} | J7: {=IFERROR(INDEX('MASTER LIST'!K:K,SMALL(IF('MASTER LIST'!$N:$N=$C$2,ROW('MASTER LIST'!$N:$N),""),ROWS(J$5:J7))),"")} | K7: {=IFERROR(INDEX('MASTER LIST'!L:L,SMALL(IF('MASTER LIST'!$N:$N=$C$2,ROW('MASTER LIST'!$N:$N),""),ROWS(K$5:K7))),"")} | L7: {=IFERROR(INDEX('MASTER LIST'!M:M,SMALL(IF('MASTER LIST'!$N:$N=$C$2,ROW('MASTER LIST'!$N:$N),""),ROWS(L$5:L7))),"")} | M7: {=IFERROR(INDEX('MASTER LIST'!N:N,SMALL(IF('MASTER LIST'!$N:$N=$C$2,ROW('MASTER LIST'!$N:$N),""),ROWS(M$5:M7))),"")} | N7: {=IFERROR(INDEX('MASTER LIST'!P:P,SMALL(IF('MASTER LIST'!$N:$N=$C$2,ROW('MASTER LIST'!$N:$N),""),ROWS(N$5:N7))),"")} | O7: {=IFERROR(INDEX('MASTER LIST'!Q:Q,SMALL(IF('MASTER LIST'!$N:$N=$C$2,ROW('MASTER LIST'!$N:$N),""),ROWS(O$5:O7))),"")} | P7: {=IFERROR(INDEX('MASTER LIST'!#REF!,SMALL(IF('MASTER LIST'!$N:$N=$C$2,ROW('MASTER LIST'!$N:$N),""),ROWS(P$5:P7))),"")} | Q7: {=IFERROR(INDEX('MASTER LIST'!R:R,SMALL(IF('MASTER LIST'!$N:$N=$C$2,ROW('MASTER LIST'!$N:$N),""),ROWS(Q$5:Q7))),"")} | R7: {=IFERROR(INDEX('MASTER LIST'!#REF!,SMALL(IF('MASTER LIST'!$N:$N=$C$2,ROW('MASTER LIST'!$N:$N),""),ROWS(R$5:R7))),"")} | S7: {=IFERROR(INDEX('MASTER LIST'!#REF!,SMALL(IF('MASTER LIST'!$N:$N=$C$2,ROW('MASTER LIST'!$N:$N),""),ROWS(S$5:S7))),"")} | T7: {=IFERROR(INDEX('MASTER LIST'!#REF!,SMALL(IF('MASTER LIST'!$N:$N=$C$2,ROW('MASTER LIST'!$N:$N),""),ROWS(T$5:T7))),"")} | U7: {=IFERROR(INDEX('MASTER LIST'!S:S,SMALL(IF('MASTER LIST'!$N:$N=$C$2,ROW('MASTER LIST'!$N:$N),""),ROWS(U$5:U7))),"")} | V7: {=IFERROR(INDEX('MASTER LIST'!T:T,SMALL(IF('MASTER LIST'!$N:$N=$C$2,ROW('MASTER LIST'!$N:$N),""),ROWS(V$5:V7))),"")} | W7: {=IFERROR(INDEX('MASTER LIST'!U:U,SMALL(IF('MASTER LIST'!$N:$N=$C$2,ROW('MASTER LIST'!$N:$N),""),ROWS(W$5:W7))),"")} | X7: {=IFERROR(INDEX('MASTER LIST'!V:V,SMALL(IF('MASTER LIST'!$N:$N=$C$2,ROW('MASTER LIST'!$N:$N),""),ROWS(X$5:X7))),"")} | Y7: {=IFERROR(INDEX('MASTER LIST'!W:W,SMALL(IF('MASTER LIST'!$N:$N=$C$2,ROW('MASTER LIST'!$N:$N),""),ROWS(Y$5:Y7))),"")}
B8: {=IFERROR(INDEX('MASTER LIST'!B:B,SMALL(IF('MASTER LIST'!$N:$N=$C$2,ROW('MASTER LIST'!$N:$N),""),ROWS(B$5:B8))),"")} | C8: {=IFERROR(INDEX('MASTER LIST'!C:C,SMALL(IF('MASTER LIST'!$N:$N=$C$2,ROW('MASTER LIST'!$N:$N),""),ROWS(C$5:C8))),"")} | D8: {=IFERROR(INDEX('MASTER LIST'!D:D,SMALL(IF('MASTER LIST'!$N:$N=$C$2,ROW('MASTER LIST'!$N:$N),""),ROWS(D$5:D8))),"")} | E8: {=IFERROR(INDEX('MASTER LIST'!E:E,SMALL(IF('MASTER LIST'!$N:$N=$C$2,ROW('MASTER LIST'!$N:$N),""),ROWS(E$5:E8))),"")} | F8: {=IFERROR(INDEX('MASTER LIST'!G:G,SMALL(IF('MASTER LIST'!$N:$N=$C$2,ROW('MASTER LIST'!$N:$N),""),ROWS(F$5:F8))),"")} | G8: {=IFERROR(INDEX('MASTER LIST'!H:H,SMALL(IF('MASTER LIST'!$N:$N=$C$2,ROW('MASTER LIST'!$N:$N),""),ROWS(G$5:G8))),"")} | H8: {=IFERROR(INDEX('MASTER LIST'!I:I,SMALL(IF('MASTER LIST'!$N:$N=$C$2,ROW('MASTER LIST'!$N:$N),""),ROWS(H$5:H8))),"")} | I8: {=IFERROR(INDEX('MASTER LIST'!J:J,SMALL(IF('MASTER LIST'!$N:$N=$C$2,ROW('MASTER LIST'!$N:$N),""),ROWS(I$5:I8))),"")} | J8: {=IFERROR(INDEX('MASTER LIST'!K:K,SMALL(IF('MASTER LIST'!$N:$N=$C$2,ROW('MASTER LIST'!$N:$N),""),ROWS(J$5:J8))),"")} | K8: {=IFERROR(INDEX('MASTER LIST'!L:L,SMALL(IF('MASTER LIST'!$N:$N=$C$2,ROW('MASTER LIST'!$N:$N),""),ROWS(K$5:K8))),"")} | L8: {=IFERROR(INDEX('MASTER LIST'!M:M,SMALL(IF('MASTER LIST'!$N:$N=$C$2,ROW('MASTER LIST'!$N:$N),""),ROWS(L$5:L8))),"")} | M8: {=IFERROR(INDEX('MASTER LIST'!N:N,SMALL(IF('MASTER LIST'!$N:$N=$C$2,ROW('MASTER LIST'!$N:$N),""),ROWS(M$5:M8))),"")} | N8: {=IFERROR(INDEX('MASTER LIST'!P:P,SMALL(IF('MASTER LIST'!$N:$N=$C$2,ROW('MASTER LIST'!$N:$N),""),ROWS(N$5:N8))),"")} | O8: {=IFERROR(INDEX('MASTER LIST'!Q:Q,SMALL(IF('MASTER LIST'!$N:$N=$C$2,ROW('MASTER LIST'!$N:$N),""),ROWS(O$5:O8))),"")} | P8: {=IFERROR(INDEX('MASTER LIST'!#REF!,SMALL(IF('MASTER LIST'!$N:$N=$C$2,ROW('MASTER LIST'!$N:$N),""),ROWS(P$5:P8))),"")} | Q8: {=IFERROR(INDEX('MASTER LIST'!R:R,SMALL(IF('MASTER LIST'!$N:$N=$C$2,ROW('MASTER LIST'!$N:$N),""),ROWS(Q$5:Q8))),"")} | R8: {=IFERROR(INDEX('MASTER LIST'!#REF!,SMALL(IF('MASTER LIST'!$N:$N=$C$2,ROW('MASTER LIST'!$N:$N),""),ROWS(R$5:R8))),"")} | S8: {=IFERROR(INDEX('MASTER LIST'!#REF!,SMALL(IF('MASTER LIST'!$N:$N=$C$2,ROW('MASTER LIST'!$N:$N),""),ROWS(S$5:S8))),"")} | T8: {=IFERROR(INDEX('MASTER LIST'!#REF!,SMALL(IF('MASTER LIST'!$N:$N=$C$2,ROW('MASTER LIST'!$N:$N),""),ROWS(T$5:T8))),"")} | U8: {=IFERROR(INDEX('MASTER LIST'!S:S,SMALL(IF('MASTER LIST'!$N:$N=$C$2,ROW('MASTER LIST'!$N:$N),""),ROWS(U$5:U8))),"")} | V8: {=IFERROR(INDEX('MASTER LIST'!T:T,SMALL(IF('MASTER LIST'!$N:$N=$C$2,ROW('MASTER LIST'!$N:$N),""),ROWS(V$5:V8))),"")} | W8: {=IFERROR(INDEX('MASTER LIST'!U:U,SMALL(IF('MASTER LIST'!$N:$N=$C$2,ROW('MASTER LIST'!$N:$N),""),ROWS(W$5:W8))),"")} | X8: {=IFERROR(INDEX('MASTER LIST'!V:V,SMALL(IF('MASTER LIST'!$N:$N=$C$2,ROW('MASTER LIST'!$N:$N),""),ROWS(X$5:X8))),"")} | Y8: {=IFERROR(INDEX('MASTER LIST'!W:W,SMALL(IF('MASTER LIST'!$N:$N=$C$2,ROW('MASTER LIST'!$N:$N),""),ROWS(Y$5:Y8))),"")}
B9: {=IFERROR(INDEX('MASTER LIST'!B:B,SMALL(IF('MASTER LIST'!$N:$N=$C$2,ROW('MASTER LIST'!$N:$N),""),ROWS(B$5:B9))),"")} | C9: {=IFERROR(INDEX('MASTER LIST'!C:C,SMALL(IF('MASTER LIST'!$N:$N=$C$2,ROW('MASTER LIST'!$N:$N),""),ROWS(C$5:C9))),"")} | D9: {=IFERROR(INDEX('MASTER LIST'!D:D,SMALL(IF('MASTER LIST'!$N:$N=$C$2,ROW('MASTER LIST'!$N:$N),""),ROWS(D$5:D9))),"")} | E9: {=IFERROR(INDEX('MASTER LIST'!E:E,SMALL(IF('MASTER LIST'!$N:$N=$C$2,ROW('MASTER LIST'!$N:$N),""),ROWS(E$5:E9))),"")} | F9: {=IFERROR(INDEX('MASTER LIST'!G:G,SMALL(IF('MASTER LIST'!$N:$N=$C$2,ROW('MASTER LIST'!$N:$N),""),ROWS(F$5:F9))),"")} | G9: {=IFERROR(INDEX('MASTER LIST'!H:H,SMALL(IF('MASTER LIST'!$N:$N=$C$2,ROW('MASTER LIST'!$N:$N),""),ROWS(G$5:G9))),"")} | H9: {=IFERROR(INDEX('MASTER LIST'!I:I,SMALL(IF('MASTER LIST'!$N:$N=$C$2,ROW('MASTER LIST'!$N:$N),""),ROWS(H$5:H9))),"")} | I9: {=IFERROR(INDEX('MASTER LIST'!J:J,SMALL(IF('MASTER LIST'!$N:$N=$C$2,ROW('MASTER LIST'!$N:$N),""),ROWS(I$5:I9))),"")} | J9: {=IFERROR(INDEX('MASTER LIST'!K:K,SMALL(IF('MASTER LIST'!$N:$N=$C$2,ROW('MASTER LIST'!$N:$N),""),ROWS(J$5:J9))),"")} | K9: {=IFERROR(INDEX('MASTER LIST'!L:L,SMALL(IF('MASTER LIST'!$N:$N=$C$2,ROW('MASTER LIST'!$N:$N),""),ROWS(K$5:K9))),"")} | L9: {=IFERROR(INDEX('MASTER LIST'!M:M,SMALL(IF('MASTER LIST'!$N:$N=$C$2,ROW('MASTER LIST'!$N:$N),""),ROWS(L$5:L9))),"")} | M9: {=IFERROR(INDEX('MASTER LIST'!N:N,SMALL(IF('MASTER LIST'!$N:$N=$C$2,ROW('MASTER LIST'!$N:$N),""),ROWS(M$5:M9))),"")} | N9: {=IFERROR(INDEX('MASTER LIST'!P:P,SMALL(IF('MASTER LIST'!$N:$N=$C$2,ROW('MASTER LIST'!$N:$N),""),ROWS(N$5:N9))),"")} | O9: {=IFERROR(INDEX('MASTER LIST'!Q:Q,SMALL(IF('MASTER LIST'!$N:$N=$C$2,ROW('MASTER LIST'!$N:$N),""),ROWS(O$5:O9))),"")} | P9: {=IFERROR(INDEX('MASTER LIST'!#REF!,SMALL(IF('MASTER LIST'!$N:$N=$C$2,ROW('MASTER LIST'!$N:$N),""),ROWS(P$5:P9))),"")} | Q9: {=IFERROR(INDEX('MASTER LIST'!R:R,SMALL(IF('MASTER LIST'!$N:$N=$C$2,ROW('MASTER LIST'!$N:$N),""),ROWS(Q$5:Q9))),"")} | R9: {=IFERROR(INDEX('MASTER LIST'!#REF!,SMALL(IF('MASTER LIST'!$N:$N=$C$2,ROW('MASTER LIST'!$N:$N),""),ROWS(R$5:R9))),"")} | S9: {=IFERROR(INDEX('MASTER LIST'!#REF!,SMALL(IF('MASTER LIST'!$N:$N=$C$2,ROW('MASTER LIST'!$N:$N),""),ROWS(S$5:S9))),"")} | T9: {=IFERROR(INDEX('MASTER LIST'!#REF!,SMALL(IF('MASTER LIST'!$N:$N=$C$2,ROW('MASTER LIST'!$N:$N),""),ROWS(T$5:T9))),"")} | U9: {=IFERROR(INDEX('MASTER LIST'!S:S,SMALL(IF('MASTER LIST'!$N:$N=$C$2,ROW('MASTER LIST'!$N:$N),""),ROWS(U$5:U9))),"")} | V9: {=IFERROR(INDEX('MASTER LIST'!T:T,SMALL(IF('MASTER LIST'!$N:$N=$C$2,ROW('MASTER LIST'!$N:$N),""),ROWS(V$5:V9))),"")} | W9: {=IFERROR(INDEX('MASTER LIST'!U:U,SMALL(IF('MASTER LIST'!$N:$N=$C$2,ROW('MASTER LIST'!$N:$N),""),ROWS(W$5:W9))),"")} | X9: {=IFERROR(INDEX('MASTER LIST'!V:V,SMALL(IF('MASTER LIST'!$N:$N=$C$2,ROW('MASTER LIST'!$N:$N),""),ROWS(X$5:X9))),"")} | Y9: {=IFERROR(INDEX('MASTER LIST'!W:W,SMALL(IF('MASTER LIST'!$N:$N=$C$2,ROW('MASTER LIST'!$N:$N),""),ROWS(Y$5:Y9))),"")}
B10: {=IFERROR(INDEX('MASTER LIST'!B:B,SMALL(IF('MASTER LIST'!$N:$N=$C$2,ROW('MASTER LIST'!$N:$N),""),ROWS(B$5:B10))),"")} | C10: {=IFERROR(INDEX('MASTER LIST'!C:C,SMALL(IF('MASTER LIST'!$N:$N=$C$2,ROW('MASTER LIST'!$N:$N),""),ROWS(C$5:C10))),"")} | D10: {=IFERROR(INDEX('MASTER LIST'!D:D,SMALL(IF('MASTER LIST'!$N:$N=$C$2,ROW('MASTER LIST'!$N:$N),""),ROWS(D$5:D10))),"")} | E10: {=IFERROR(INDEX('MASTER LIST'!E:E,SMALL(IF('MASTER LIST'!$N:$N=$C$2,ROW('MASTER LIST'!$N:$N),""),ROWS(E$5:E10))),"")} | F10: {=IFERROR(INDEX('MASTER LIST'!G:G,SMALL(IF('MASTER LIST'!$N:$N=$C$2,ROW('MASTER LIST'!$N:$N),""),ROWS(F$5:F10))),"")} | G10: {=IFERROR(INDEX('MASTER LIST'!H:H,SMALL(IF('MASTER LIST'!$N:$N=$C$2,ROW('MASTER LIST'!$N:$N),""),ROWS(G$5:G10))),"")} | H10: {=IFERROR(INDEX('MASTER LIST'!I:I,SMALL(IF('MASTER LIST'!$N:$N=$C$2,ROW('MASTER LIST'!$N:$N),""),ROWS(H$5:H10))),"")} | I10: {=IFERROR(INDEX('MASTER LIST'!J:J,SMALL(IF('MASTER LIST'!$N:$N=$C$2,ROW('MASTER LIST'!$N:$N),""),ROWS(I$5:I10))),"")} | J10: {=IFERROR(INDEX('MASTER LIST'!K:K,SMALL(IF('MASTER LIST'!$N:$N=$C$2,ROW('MASTER LIST'!$N:$N),""),ROWS(J$5:J10))),"")} | K10: {=IFERROR(INDEX('MASTER LIST'!L:L,SMALL(IF('MASTER LIST'!$N:$N=$C$2,ROW('MASTER LIST'!$N:$N),""),ROWS(K$5:K10))),"")} | L10: {=IFERROR(INDEX('MASTER LIST'!M:M,SMALL(IF('MASTER LIST'!$N:$N=$C$2,ROW('MASTER LIST'!$N:$N),""),ROWS(L$5:L10))),"")} | M10: {=IFERROR(INDEX('MASTER LIST'!N:N,SMALL(IF('MASTER LIST'!$N:$N=$C$2,ROW('MASTER LIST'!$N:$N),""),ROWS(M$5:M10))),"")} | N10: {=IFERROR(INDEX('MASTER LIST'!P:P,SMALL(IF('MASTER LIST'!$N:$N=$C$2,ROW('MASTER LIST'!$N:$N),""),ROWS(N$5:N10))),"")} | O10: {=IFERROR(INDEX('MASTER LIST'!Q:Q,SMALL(IF('MASTER LIST'!$N:$N=$C$2,ROW('MASTER LIST'!$N:$N),""),ROWS(O$5:O10))),"")} | P10: {=IFERROR(INDEX('MASTER LIST'!#REF!,SMALL(IF('MASTER LIST'!$N:$N=$C$2,ROW('MASTER LIST'!$N:$N),""),ROWS(P$5:P10))),"")} | Q10: {=IFERROR(INDEX('MASTER LIST'!R:R,SMALL(IF('MASTER LIST'!$N:$N=$C$2,ROW('MASTER LIST'!$N:$N),""),ROWS(Q$5:Q10))),"")} | R10: {=IFERROR(INDEX('MASTER LIST'!#REF!,SMALL(IF('MASTER LIST'!$N:$N=$C$2,ROW('MASTER LIST'!$N:$N),""),ROWS(R$5:R10))),"")} | S10: {=IFERROR(INDEX('MASTER LIST'!#REF!,SMALL(IF('MASTER LIST'!$N:$N=$C$2,ROW('MASTER LIST'!$N:$N),""),ROWS(S$5:S10))),"")} | T10: {=IFERROR(INDEX('MASTER LIST'!#REF!,SMALL(IF('MASTER LIST'!$N:$N=$C$2,ROW('MASTER LIST'!$N:$N),""),ROWS(T$5:T10))),"")} | U10: {=IFERROR(INDEX('MASTER LIST'!S:S,SMALL(IF('MASTER LIST'!$N:$N=$C$2,ROW('MASTER LIST'!$N:$N),""),ROWS(U$5:U10))),"")} | V10: {=IFERROR(INDEX('MASTER LIST'!T:T,SMALL(IF('MASTER LIST'!$N:$N=$C$2,ROW('MASTER LIST'!$N:$N),""),ROWS(V$5:V10))),"")} | W10: {=IFERROR(INDEX('MASTER LIST'!U:U,SMALL(IF('MASTER LIST'!$N:$N=$C$2,ROW('MASTER LIST'!$N:$N),""),ROWS(W$5:W10))),"")} | X10: {=IFERROR(INDEX('MASTER LIST'!V:V,SMALL(IF('MASTER LIST'!$N:$N=$C$2,ROW('MASTER LIST'!$N:$N),""),ROWS(X$5:X10))),"")} | Y10: {=IFERROR(INDEX('MASTER LIST'!W:W,SMALL(IF('MASTER LIST'!$N:$N=$C$2,ROW('MASTER LIST'!$N:$N),""),ROWS(Y$5:Y10))),"")}
B11: {=IFERROR(INDEX('MASTER LIST'!B:B,SMALL(IF('MASTER LIST'!$N:$N=$C$2,ROW('MASTER LIST'!$N:$N),""),ROWS(B$5:B11))),"")} | C11: {=IFERROR(INDEX('MASTER LIST'!C:C,SMALL(IF('MASTER LIST'!$N:$N=$C$2,ROW('MASTER LIST'!$N:$N),""),ROWS(C$5:C11))),"")} | D11: {=IFERROR(INDEX('MASTER LIST'!D:D,SMALL(IF('MASTER LIST'!$N:$N=$C$2,ROW('MASTER LIST'!$N:$N),""),ROWS(D$5:D11))),"")} | E11: {=IFERROR(INDEX('MASTER LIST'!E:E,SMALL(IF('MASTER LIST'!$N:$N=$C$2,ROW('MASTER LIST'!$N:$N),""),ROWS(E$5:E11))),"")} | F11: {=IFERROR(INDEX('MASTER LIST'!G:G,SMALL(IF('MASTER LIST'!$N:$N=$C$2,ROW('MASTER LIST'!$N:$N),""),ROWS(F$5:F11))),"")} | G11: {=IFERROR(INDEX('MASTER LIST'!H:H,SMALL(IF('MASTER LIST'!$N:$N=$C$2,ROW('MASTER LIST'!$N:$N),""),ROWS(G$5:G11))),"")} | H11: {=IFERROR(INDEX('MASTER LIST'!I:I,SMALL(IF('MASTER LIST'!$N:$N=$C$2,ROW('MASTER LIST'!$N:$N),""),ROWS(H$5:H11))),"")} | I11: {=IFERROR(INDEX('MASTER LIST'!J:J,SMALL(IF('MASTER LIST'!$N:$N=$C$2,ROW('MASTER LIST'!$N:$N),""),ROWS(I$5:I11))),"")} | J11: {=IFERROR(INDEX('MASTER LIST'!K:K,SMALL(IF('MASTER LIST'!$N:$N=$C$2,ROW('MASTER LIST'!$N:$N),""),ROWS(J$5:J11))),"")} | K11: {=IFERROR(INDEX('MASTER LIST'!L:L,SMALL(IF('MASTER LIST'!$N:$N=$C$2,ROW('MASTER LIST'!$N:$N),""),ROWS(K$5:K11))),"")} | L11: {=IFERROR(INDEX('MASTER LIST'!M:M,SMALL(IF('MASTER LIST'!$N:$N=$C$2,ROW('MASTER LIST'!$N:$N),""),ROWS(L$5:L11))),"")} | M11: {=IFERROR(INDEX('MASTER LIST'!N:N,SMALL(IF('MASTER LIST'!$N:$N=$C$2,ROW('MASTER LIST'!$N:$N),""),ROWS(M$5:M11))),"")} | N11: {=IFERROR(INDEX('MASTER LIST'!P:P,SMALL(IF('MASTER LIST'!$N:$N=$C$2,ROW('MASTER LIST'!$N:$N),""),ROWS(N$5:N11))),"")} | O11: {=IFERROR(INDEX('MASTER LIST'!Q:Q,SMALL(IF('MASTER LIST'!$N:$N=$C$2,ROW('MASTER LIST'!$N:$N),""),ROWS(O$5:O11))),"")} | P11: {=IFERROR(INDEX('MASTER LIST'!#REF!,SMALL(IF('MASTER LIST'!$N:$N=$C$2,ROW('MASTER LIST'!$N:$N),""),ROWS(P$5:P11))),"")} | Q11: {=IFERROR(INDEX('MASTER LIST'!R:R,SMALL(IF('MASTER LIST'!$N:$N=$C$2,ROW('MASTER LIST'!$N:$N),""),ROWS(Q$5:Q11))),"")} | R11: {=IFERROR(INDEX('MASTER LIST'!#REF!,SMALL(IF('MASTER LIST'!$N:$N=$C$2,ROW('MASTER LIST'!$N:$N),""),ROWS(R$5:R11))),"")} | S11: {=IFERROR(INDEX('MASTER LIST'!#REF!,SMALL(IF('MASTER LIST'!$N:$N=$C$2,ROW('MASTER LIST'!$N:$N),""),ROWS(S$5:S11))),"")} | T11: {=IFERROR(INDEX('MASTER LIST'!#REF!,SMALL(IF('MASTER LIST'!$N:$N=$C$2,ROW('MASTER LIST'!$N:$N),""),ROWS(T$5:T11))),"")} | U11: {=IFERROR(INDEX('MASTER LIST'!S:S,SMALL(IF('MASTER LIST'!$N:$N=$C$2,ROW('MASTER LIST'!$N:$N),""),ROWS(U$5:U11))),"")} | V11: {=IFERROR(INDEX('MASTER LIST'!T:T,SMALL(IF('MASTER LIST'!$N:$N=$C$2,ROW('MASTER LIST'!$N:$N),""),ROWS(V$5:V11))),"")} | W11: {=IFERROR(INDEX('MASTER LIST'!U:U,SMALL(IF('MASTER LIST'!$N:$N=$C$2,ROW('MASTER LIST'!$N:$N),""),ROWS(W$5:W11))),"")} | X11: {=IFERROR(INDEX('MASTER LIST'!V:V,SMALL(IF('MASTER LIST'!$N:$N=$C$2,ROW('MASTER LIST'!$N:$N),""),ROWS(X$5:X11))),"")} | Y11: {=IFERROR(INDEX('MASTER LIST'!W:W,SMALL(IF('MASTER LIST'!$N:$N=$C$2,ROW('MASTER LIST'!$N:$N),""),ROWS(Y$5:Y11))),"")}
B12: {=IFERROR(INDEX('MASTER LIST'!B:B,SMALL(IF('MASTER LIST'!$N:$N=$C$2,ROW('MASTER LIST'!$N:$N),""),ROWS(B$5:B12))),"")} | C12: {=IFERROR(INDEX('MASTER LIST'!C:C,SMALL(IF('MASTER LIST'!$N:$N=$C$2,ROW('MASTER LIST'!$N:$N),""),ROWS(C$5:C12))),"")} | D12: {=IFERROR(INDEX('MASTER LIST'!D:D,SMALL(IF('MASTER LIST'!$N:$N=$C$2,ROW('MASTER LIST'!$N:$N),""),ROWS(D$5:D12))),"")} | E12: {=IFERROR(INDEX('MASTER LIST'!E:E,SMALL(IF('MASTER LIST'!$N:$N=$C$2,ROW('MASTER LIST'!$N:$N),""),ROWS(E$5:E12))),"")} | F12: {=IFERROR(INDEX('MASTER LIST'!G:G,SMALL(IF('MASTER LIST'!$N:$N=$C$2,ROW('MASTER LIST'!$N:$N),""),ROWS(F$5:F12))),"")} | G12: {=IFERROR(INDEX('MASTER LIST'!H:H,SMALL(IF('MASTER LIST'!$N:$N=$C$2,ROW('MASTER LIST'!$N:$N),""),ROWS(G$5:G12))),"")} | H12: {=IFERROR(INDEX('MASTER LIST'!I:I,SMALL(IF('MASTER LIST'!$N:$N=$C$2,ROW('MASTER LIST'!$N:$N),""),ROWS(H$5:H12))),"")} | I12: {=IFERROR(INDEX('MASTER LIST'!J:J,SMALL(IF('MASTER LIST'!$N:$N=$C$2,ROW('MASTER LIST'!$N:$N),""),ROWS(I$5:I12))),"")} | J12: {=IFERROR(INDEX('MASTER LIST'!K:K,SMALL(IF('MASTER LIST'!$N:$N=$C$2,ROW('MASTER LIST'!$N:$N),""),ROWS(J$5:J12))),"")} | K12: {=IFERROR(INDEX('MASTER LIST'!L:L,SMALL(IF('MASTER LIST'!$N:$N=$C$2,ROW('MASTER LIST'!$N:$N),""),ROWS(K$5:K12))),"")} | L12: {=IFERROR(INDEX('MASTER LIST'!M:M,SMALL(IF('MASTER LIST'!$N:$N=$C$2,ROW('MASTER LIST'!$N:$N),""),ROWS(L$5:L12))),"")} | M12: {=IFERROR(INDEX('MASTER LIST'!N:N,SMALL(IF('MASTER LIST'!$N:$N=$C$2,ROW('MASTER LIST'!$N:$N),""),ROWS(M$5:M12))),"")} | N12: {=IFERROR(INDEX('MASTER LIST'!P:P,SMALL(IF('MASTER LIST'!$N:$N=$C$2,ROW('MASTER LIST'!$N:$N),""),ROWS(N$5:N12))),"")} | O12: {=IFERROR(INDEX('MASTER LIST'!Q:Q,SMALL(IF('MASTER LIST'!$N:$N=$C$2,ROW('MASTER LIST'!$N:$N),""),ROWS(O$5:O12))),"")} | P12: {=IFERROR(INDEX('MASTER LIST'!#REF!,SMALL(IF('MASTER LIST'!$N:$N=$C$2,ROW('MASTER LIST'!$N:$N),""),ROWS(P$5:P12))),"")} | Q12: {=IFERROR(INDEX('MASTER LIST'!R:R,SMALL(IF('MASTER LIST'!$N:$N=$C$2,ROW('MASTER LIST'!$N:$N),""),ROWS(Q$5:Q12))),"")} | R12: {=IFERROR(INDEX('MASTER LIST'!#REF!,SMALL(IF('MASTER LIST'!$N:$N=$C$2,ROW('MASTER LIST'!$N:$N),""),ROWS(R$5:R12))),"")} | S12: {=IFERROR(INDEX('MASTER LIST'!#REF!,SMALL(IF('MASTER LIST'!$N:$N=$C$2,ROW('MASTER LIST'!$N:$N),""),ROWS(S$5:S12))),"")} | T12: {=IFERROR(INDEX('MASTER LIST'!#REF!,SMALL(IF('MASTER LIST'!$N:$N=$C$2,ROW('MASTER LIST'!$N:$N),""),ROWS(T$5:T12))),"")} | U12: {=IFERROR(INDEX('MASTER LIST'!S:S,SMALL(IF('MASTER LIST'!$N:$N=$C$2,ROW('MASTER LIST'!$N:$N),""),ROWS(U$5:U12))),"")} | V12: {=IFERROR(INDEX('MASTER LIST'!T:T,SMALL(IF('MASTER LIST'!$N:$N=$C$2,ROW('MASTER LIST'!$N:$N),""),ROWS(V$5:V12))),"")} | W12: {=IFERROR(INDEX('MASTER LIST'!U:U,SMALL(IF('MASTER LIST'!$N:$N=$C$2,ROW('MASTER LIST'!$N:$N),""),ROWS(W$5:W12))),"")} | X12: {=IFERROR(INDEX('MASTER LIST'!V:V,SMALL(IF('MASTER LIST'!$N:$N=$C$2,ROW('MASTER LIST'!$N:$N),""),ROWS(X$5:X12))),"")} | Y12: {=IFERROR(INDEX('MASTER LIST'!W:W,SMALL(IF('MASTER LIST'!$N:$N=$C$2,ROW('MASTER LIST'!$N:$N),""),ROWS(Y$5:Y12))),"")}
B13: {=IFERROR(INDEX('MASTER LIST'!B:B,SMALL(IF('MASTER LIST'!$N:$N=$C$2,ROW('MASTER LIST'!$N:$N),""),ROWS(B$5:B13))),"")} | C13: {=IFERROR(INDEX('MASTER LIST'!C:C,SMALL(IF('MASTER LIST'!$N:$N=$C$2,ROW('MASTER LIST'!$N:$N),""),ROWS(C$5:C13))),"")} | D13: {=IFERROR(INDEX('MASTER LIST'!D:D,SMALL(IF('MASTER LIST'!$N:$N=$C$2,ROW('MASTER LIST'!$N:$N),""),ROWS(D$5:D13))),"")} | E13: {=IFERROR(INDEX('MASTER LIST'!E:E,SMALL(IF('MASTER LIST'!$N:$N=$C$2,ROW('MASTER LIST'!$N:$N),""),ROWS(E$5:E13))),"")} | F13: {=IFERROR(INDEX('MASTER LIST'!G:G,SMALL(IF('MASTER LIST'!$N:$N=$C$2,ROW('MASTER LIST'!$N:$N),""),ROWS(F$5:F13))),"")} | G13: {=IFERROR(INDEX('MASTER LIST'!H:H,SMALL(IF('MASTER LIST'!$N:$N=$C$2,ROW('MASTER LIST'!$N:$N),""),ROWS(G$5:G13))),"")} | H13: {=IFERROR(INDEX('MASTER LIST'!I:I,SMALL(IF('MASTER LIST'!$N:$N=$C$2,ROW('MASTER LIST'!$N:$N),""),ROWS(H$5:H13))),"")} | I13: {=IFERROR(INDEX('MASTER LIST'!J:J,SMALL(IF('MASTER LIST'!$N:$N=$C$2,ROW('MASTER LIST'!$N:$N),""),ROWS(I$5:I13))),"")} | J13: {=IFERROR(INDEX('MASTER LIST'!K:K,SMALL(IF('MASTER LIST'!$N:$N=$C$2,ROW('MASTER LIST'!$N:$N),""),ROWS(J$5:J13))),"")} | K13: {=IFERROR(INDEX('MASTER LIST'!L:L,SMALL(IF('MASTER LIST'!$N:$N=$C$2,ROW('MASTER LIST'!$N:$N),""),ROWS(K$5:K13))),"")} | L13: {=IFERROR(INDEX('MASTER LIST'!M:M,SMALL(IF('MASTER LIST'!$N:$N=$C$2,ROW('MASTER LIST'!$N:$N),""),ROWS(L$5:L13))),"")} | M13: {=IFERROR(INDEX('MASTER LIST'!N:N,SMALL(IF('MASTER LIST'!$N:$N=$C$2,ROW('MASTER LIST'!$N:$N),""),ROWS(M$5:M13))),"")} | N13: {=IFERROR(INDEX('MASTER LIST'!P:P,SMALL(IF('MASTER LIST'!$N:$N=$C$2,ROW('MASTER LIST'!$N:$N),""),ROWS(N$5:N13))),"")} | O13: {=IFERROR(INDEX('MASTER LIST'!Q:Q,SMALL(IF('MASTER LIST'!$N:$N=$C$2,ROW('MASTER LIST'!$N:$N),""),ROWS(O$5:O13))),"")} | P13: {=IFERROR(INDEX('MASTER LIST'!#REF!,SMALL(IF('MASTER LIST'!$N:$N=$C$2,ROW('MASTER LIST'!$N:$N),""),ROWS(P$5:P13))),"")} | Q13: {=IFERROR(INDEX('MASTER LIST'!R:R,SMALL(IF('MASTER LIST'!$N:$N=$C$2,ROW('MASTER LIST'!$N:$N),""),ROWS(Q$5:Q13))),"")} | R13: {=IFERROR(INDEX('MASTER LIST'!#REF!,SMALL(IF('MASTER LIST'!$N:$N=$C$2,ROW('MASTER LIST'!$N:$N),""),ROWS(R$5:R13))),"")} | S13: {=IFERROR(INDEX('MASTER LIST'!#REF!,SMALL(IF('MASTER LIST'!$N:$N=$C$2,ROW('MASTER LIST'!$N:$N),""),ROWS(S$5:S13))),"")} | T13: {=IFERROR(INDEX('MASTER LIST'!#REF!,SMALL(IF('MASTER LIST'!$N:$N=$C$2,ROW('MASTER LIST'!$N:$N),""),ROWS(T$5:T13))),"")} | U13: {=IFERROR(INDEX('MASTER LIST'!S:S,SMALL(IF('MASTER LIST'!$N:$N=$C$2,ROW('MASTER LIST'!$N:$N),""),ROWS(U$5:U13))),"")} | V13: {=IFERROR(INDEX('MASTER LIST'!T:T,SMALL(IF('MASTER LIST'!$N:$N=$C$2,ROW('MASTER LIST'!$N:$N),""),ROWS(V$5:V13))),"")} | W13: {=IFERROR(INDEX('MASTER LIST'!U:U,SMALL(IF('MASTER LIST'!$N:$N=$C$2,ROW('MASTER LIST'!$N:$N),""),ROWS(W$5:W13))),"")} | X13: {=IFERROR(INDEX('MASTER LIST'!V:V,SMALL(IF('MASTER LIST'!$N:$N=$C$2,ROW('MASTER LIST'!$N:$N),""),ROWS(X$5:X13))),"")} | Y13: {=IFERROR(INDEX('MASTER LIST'!W:W,SMALL(IF('MASTER LIST'!$N:$N=$C$2,ROW('MASTER LIST'!$N:$N),""),ROWS(Y$5:Y13))),"")}
B14: {=IFERROR(INDEX('MASTER LIST'!B:B,SMALL(IF('MASTER LIST'!$N:$N=$C$2,ROW('MASTER LIST'!$N:$N),""),ROWS(B$5:B14))),"")} | C14: {=IFERROR(INDEX('MASTER LIST'!C:C,SMALL(IF('MASTER LIST'!$N:$N=$C$2,ROW('MASTER LIST'!$N:$N),""),ROWS(C$5:C14))),"")} | D14: {=IFERROR(INDEX('MASTER LIST'!D:D,SMALL(IF('MASTER LIST'!$N:$N=$C$2,ROW('MASTER LIST'!$N:$N),""),ROWS(D$5:D14))),"")} | E14: {=IFERROR(INDEX('MASTER LIST'!E:E,SMALL(IF('MASTER LIST'!$N:$N=$C$2,ROW('MASTER LIST'!$N:$N),""),ROWS(E$5:E14))),"")} | F14: {=IFERROR(INDEX('MASTER LIST'!G:G,SMALL(IF('MASTER LIST'!$N:$N=$C$2,ROW('MASTER LIST'!$N:$N),""),ROWS(F$5:F14))),"")} | G14: {=IFERROR(INDEX('MASTER LIST'!H:H,SMALL(IF('MASTER LIST'!$N:$N=$C$2,ROW('MASTER LIST'!$N:$N),""),ROWS(G$5:G14))),"")} | H14: {=IFERROR(INDEX('MASTER LIST'!I:I,SMALL(IF('MASTER LIST'!$N:$N=$C$2,ROW('MASTER LIST'!$N:$N),""),ROWS(H$5:H14))),"")} | I14: {=IFERROR(INDEX('MASTER LIST'!J:J,SMALL(IF('MASTER LIST'!$N:$N=$C$2,ROW('MASTER LIST'!$N:$N),""),ROWS(I$5:I14))),"")} | J14: {=IFERROR(INDEX('MASTER LIST'!K:K,SMALL(IF('MASTER LIST'!$N:$N=$C$2,ROW('MASTER LIST'!$N:$N),""),ROWS(J$5:J14))),"")} | K14: {=IFERROR(INDEX('MASTER LIST'!L:L,SMALL(IF('MASTER LIST'!$N:$N=$C$2,ROW('MASTER LIST'!$N:$N),""),ROWS(K$5:K14))),"")} | L14: {=IFERROR(INDEX('MASTER LIST'!M:M,SMALL(IF('MASTER LIST'!$N:$N=$C$2,ROW('MASTER LIST'!$N:$N),""),ROWS(L$5:L14))),"")} | M14: {=IFERROR(INDEX('MASTER LIST'!N:N,SMALL(IF('MASTER LIST'!$N:$N=$C$2,ROW('MASTER LIST'!$N:$N),""),ROWS(M$5:M14))),"")} | N14: {=IFERROR(INDEX('MASTER LIST'!P:P,SMALL(IF('MASTER LIST'!$N:$N=$C$2,ROW('MASTER LIST'!$N:$N),""),ROWS(N$5:N14))),"")} | O14: {=IFERROR(INDEX('MASTER LIST'!Q:Q,SMALL(IF('MASTER LIST'!$N:$N=$C$2,ROW('MASTER LIST'!$N:$N),""),ROWS(O$5:O14))),"")} | P14: {=IFERROR(INDEX('MASTER LIST'!#REF!,SMALL(IF('MASTER LIST'!$N:$N=$C$2,ROW('MASTER LIST'!$N:$N),""),ROWS(P$5:P14))),"")} | Q14: {=IFERROR(INDEX('MASTER LIST'!R:R,SMALL(IF('MASTER LIST'!$N:$N=$C$2,ROW('MASTER LIST'!$N:$N),""),ROWS(Q$5:Q14))),"")} | R14: {=IFERROR(INDEX('MASTER LIST'!#REF!,SMALL(IF('MASTER LIST'!$N:$N=$C$2,ROW('MASTER LIST'!$N:$N),""),ROWS(R$5:R14))),"")} | S14: {=IFERROR(INDEX('MASTER LIST'!#REF!,SMALL(IF('MASTER LIST'!$N:$N=$C$2,ROW('MASTER LIST'!$N:$N),""),ROWS(S$5:S14))),"")} | T14: {=IFERROR(INDEX('MASTER LIST'!#REF!,SMALL(IF('MASTER LIST'!$N:$N=$C$2,ROW('MASTER LIST'!$N:$N),""),ROWS(T$5:T14))),"")} | U14: {=IFERROR(INDEX('MASTER LIST'!S:S,SMALL(IF('MASTER LIST'!$N:$N=$C$2,ROW('MASTER LIST'!$N:$N),""),ROWS(U$5:U14))),"")} | V14: {=IFERROR(INDEX('MASTER LIST'!T:T,SMALL(IF('MASTER LIST'!$N:$N=$C$2,ROW('MASTER LIST'!$N:$N),""),ROWS(V$5:V14))),"")} | W14: {=IFERROR(INDEX('MASTER LIST'!U:U,SMALL(IF('MASTER LIST'!$N:$N=$C$2,ROW('MASTER LIST'!$N:$N),""),ROWS(W$5:W14))),"")} | X14: {=IFERROR(INDEX('MASTER LIST'!V:V,SMALL(IF('MASTER LIST'!$N:$N=$C$2,ROW('MASTER LIST'!$N:$N),""),ROWS(X$5:X14))),"")} | Y14: {=IFERROR(INDEX('MASTER LIST'!W:W,SMALL(IF('MASTER LIST'!$N:$N=$C$2,ROW('MASTER LIST'!$N:$N),""),ROWS(Y$5:Y14))),"")}
B15: {=IFERROR(INDEX('MASTER LIST'!B:B,SMALL(IF('MASTER LIST'!$N:$N=$C$2,ROW('MASTER LIST'!$N:$N),""),ROWS(B$5:B15))),"")} | C15: {=IFERROR(INDEX('MASTER LIST'!C:C,SMALL(IF('MASTER LIST'!$N:$N=$C$2,ROW('MASTER LIST'!$N:$N),""),ROWS(C$5:C15))),"")} | D15: {=IFERROR(INDEX('MASTER LIST'!D:D,SMALL(IF('MASTER LIST'!$N:$N=$C$2,ROW('MASTER LIST'!$N:$N),""),ROWS(D$5:D15))),"")} | E15: {=IFERROR(INDEX('MASTER LIST'!E:E,SMALL(IF('MASTER LIST'!$N:$N=$C$2,ROW('MASTER LIST'!$N:$N),""),ROWS(E$5:E15))),"")} | F15: {=IFERROR(INDEX('MASTER LIST'!G:G,SMALL(IF('MASTER LIST'!$N:$N=$C$2,ROW('MASTER LIST'!$N:$N),""),ROWS(F$5:F15))),"")} | G15: {=IFERROR(INDEX('MASTER LIST'!H:H,SMALL(IF('MASTER LIST'!$N:$N=$C$2,ROW('MASTER LIST'!$N:$N),""),ROWS(G$5:G15))),"")} | H15: {=IFERROR(INDEX('MASTER LIST'!I:I,SMALL(IF('MASTER LIST'!$N:$N=$C$2,ROW('MASTER LIST'!$N:$N),""),ROWS(H$5:H15))),"")} | I15: {=IFERROR(INDEX('MASTER LIST'!J:J,SMALL(IF('MASTER LIST'!$N:$N=$C$2,ROW('MASTER LIST'!$N:$N),""),ROWS(I$5:I15))),"")} | J15: {=IFERROR(INDEX('MASTER LIST'!K:K,SMALL(IF('MASTER LIST'!$N:$N=$C$2,ROW('MASTER LIST'!$N:$N),""),ROWS(J$5:J15))),"")} | K15: {=IFERROR(INDEX('MASTER LIST'!L:L,SMALL(IF('MASTER LIST'!$N:$N=$C$2,ROW('MASTER LIST'!$N:$N),""),ROWS(K$5:K15))),"")} | L15: {=IFERROR(INDEX('MASTER LIST'!M:M,SMALL(IF('MASTER LIST'!$N:$N=$C$2,ROW('MASTER LIST'!$N:$N),""),ROWS(L$5:L15))),"")} | M15: {=IFERROR(INDEX('MASTER LIST'!N:N,SMALL(IF('MASTER LIST'!$N:$N=$C$2,ROW('MASTER LIST'!$N:$N),""),ROWS(M$5:M15))),"")} | N15: {=IFERROR(INDEX('MASTER LIST'!P:P,SMALL(IF('MASTER LIST'!$N:$N=$C$2,ROW('MASTER LIST'!$N:$N),""),ROWS(N$5:N15))),"")} | O15: {=IFERROR(INDEX('MASTER LIST'!Q:Q,SMALL(IF('MASTER LIST'!$N:$N=$C$2,ROW('MASTER LIST'!$N:$N),""),ROWS(O$5:O15))),"")} | P15: {=IFERROR(INDEX('MASTER LIST'!#REF!,SMALL(IF('MASTER LIST'!$N:$N=$C$2,ROW('MASTER LIST'!$N:$N),""),ROWS(P$5:P15))),"")} | Q15: {=IFERROR(INDEX('MASTER LIST'!R:R,SMALL(IF('MASTER LIST'!$N:$N=$C$2,ROW('MASTER LIST'!$N:$N),""),ROWS(Q$5:Q15))),"")} | R15: {=IFERROR(INDEX('MASTER LIST'!#REF!,SMALL(IF('MASTER LIST'!$N:$N=$C$2,ROW('MASTER LIST'!$N:$N),""),ROWS(R$5:R15))),"")} | S15: {=IFERROR(INDEX('MASTER LIST'!#REF!,SMALL(IF('MASTER LIST'!$N:$N=$C$2,ROW('MASTER LIST'!$N:$N),""),ROWS(S$5:S15))),"")} | T15: {=IFERROR(INDEX('MASTER LIST'!#REF!,SMALL(IF('MASTER LIST'!$N:$N=$C$2,ROW('MASTER LIST'!$N:$N),""),ROWS(T$5:T15))),"")} | U15: {=IFERROR(INDEX('MASTER LIST'!S:S,SMALL(IF('MASTER LIST'!$N:$N=$C$2,ROW('MASTER LIST'!$N:$N),""),ROWS(U$5:U15))),"")} | V15: {=IFERROR(INDEX('MASTER LIST'!T:T,SMALL(IF('MASTER LIST'!$N:$N=$C$2,ROW('MASTER LIST'!$N:$N),""),ROWS(V$5:V15))),"")} | W15: {=IFERROR(INDEX('MASTER LIST'!U:U,SMALL(IF('MASTER LIST'!$N:$N=$C$2,ROW('MASTER LIST'!$N:$N),""),ROWS(W$5:W15))),"")} | X15: {=IFERROR(INDEX('MASTER LIST'!V:V,SMALL(IF('MASTER LIST'!$N:$N=$C$2,ROW('MASTER LIST'!$N:$N),""),ROWS(X$5:X15))),"")} | Y15: {=IFERROR(INDEX('MASTER LIST'!W:W,SMALL(IF('MASTER LIST'!$N:$N=$C$2,ROW('MASTER LIST'!$N:$N),""),ROWS(Y$5:Y15))),"")}
B16: {=IFERROR(INDEX('MASTER LIST'!B:B,SMALL(IF('MASTER LIST'!$N:$N=$C$2,ROW('MASTER LIST'!$N:$N),""),ROWS(B$5:B16))),"")} | C16: {=IFERROR(INDEX('MASTER LIST'!C:C,SMALL(IF('MASTER LIST'!$N:$N=$C$2,ROW('MASTER LIST'!$N:$N),""),ROWS(C$5:C16))),"")} | D16: {=IFERROR(INDEX('MASTER LIST'!D:D,SMALL(IF('MASTER LIST'!$N:$N=$C$2,ROW('MASTER LIST'!$N:$N),""),ROWS(D$5:D16))),"")} | E16: {=IFERROR(INDEX('MASTER LIST'!E:E,SMALL(IF('MASTER LIST'!$N:$N=$C$2,ROW('MASTER LIST'!$N:$N),""),ROWS(E$5:E16))),"")} | F16: {=IFERROR(INDEX('MASTER LIST'!G:G,SMALL(IF('MASTER LIST'!$N:$N=$C$2,ROW('MASTER LIST'!$N:$N),""),ROWS(F$5:F16))),"")} | G16: {=IFERROR(INDEX('MASTER LIST'!H:H,SMALL(IF('MASTER LIST'!$N:$N=$C$2,ROW('MASTER LIST'!$N:$N),""),ROWS(G$5:G16))),"")} | H16: {=IFERROR(INDEX('MASTER LIST'!I:I,SMALL(IF('MASTER LIST'!$N:$N=$C$2,ROW('MASTER LIST'!$N:$N),""),ROWS(H$5:H16))),"")} | I16: {=IFERROR(INDEX('MASTER LIST'!J:J,SMALL(IF('MASTER LIST'!$N:$N=$C$2,ROW('MASTER LIST'!$N:$N),""),ROWS(I$5:I16))),"")} | J16: {=IFERROR(INDEX('MASTER LIST'!K:K,SMALL(IF('MASTER LIST'!$N:$N=$C$2,ROW('MASTER LIST'!$N:$N),""),ROWS(J$5:J16))),"")} | K16: {=IFERROR(INDEX('MASTER LIST'!L:L,SMALL(IF('MASTER LIST'!$N:$N=$C$2,ROW('MASTER LIST'!$N:$N),""),ROWS(K$5:K16))),"")} | L16: {=IFERROR(INDEX('MASTER LIST'!M:M,SMALL(IF('MASTER LIST'!$N:$N=$C$2,ROW('MASTER LIST'!$N:$N),""),ROWS(L$5:L16))),"")} | M16: {=IFERROR(INDEX('MASTER LIST'!N:N,SMALL(IF('MASTER LIST'!$N:$N=$C$2,ROW('MASTER LIST'!$N:$N),""),ROWS(M$5:M16))),"")} | N16: {=IFERROR(INDEX('MASTER LIST'!P:P,SMALL(IF('MASTER LIST'!$N:$N=$C$2,ROW('MASTER LIST'!$N:$N),""),ROWS(N$5:N16))),"")} | O16: {=IFERROR(INDEX('MASTER LIST'!Q:Q,SMALL(IF('MASTER LIST'!$N:$N=$C$2,ROW('MASTER LIST'!$N:$N),""),ROWS(O$5:O16))),"")} | P16: {=IFERROR(INDEX('MASTER LIST'!#REF!,SMALL(IF('MASTER LIST'!$N:$N=$C$2,ROW('MASTER LIST'!$N:$N),""),ROWS(P$5:P16))),"")} | Q16: {=IFERROR(INDEX('MASTER LIST'!R:R,SMALL(IF('MASTER LIST'!$N:$N=$C$2,ROW('MASTER LIST'!$N:$N),""),ROWS(Q$5:Q16))),"")} | R16: {=IFERROR(INDEX('MASTER LIST'!#REF!,SMALL(IF('MASTER LIST'!$N:$N=$C$2,ROW('MASTER LIST'!$N:$N),""),ROWS(R$5:R16))),"")} | S16: {=IFERROR(INDEX('MASTER LIST'!#REF!,SMALL(IF('MASTER LIST'!$N:$N=$C$2,ROW('MASTER LIST'!$N:$N),""),ROWS(S$5:S16))),"")} | T16: {=IFERROR(INDEX('MASTER LIST'!#REF!,SMALL(IF('MASTER LIST'!$N:$N=$C$2,ROW('MASTER LIST'!$N:$N),""),ROWS(T$5:T16))),"")} | U16: {=IFERROR(INDEX('MASTER LIST'!S:S,SMALL(IF('MASTER LIST'!$N:$N=$C$2,ROW('MASTER LIST'!$N:$N),""),ROWS(U$5:U16))),"")} | V16: {=IFERROR(INDEX('MASTER LIST'!T:T,SMALL(IF('MASTER LIST'!$N:$N=$C$2,ROW('MASTER LIST'!$N:$N),""),ROWS(V$5:V16))),"")} | W16: {=IFERROR(INDEX('MASTER LIST'!U:U,SMALL(IF('MASTER LIST'!$N:$N=$C$2,ROW('MASTER LIST'!$N:$N),""),ROWS(W$5:W16))),"")} | X16: {=IFERROR(INDEX('MASTER LIST'!V:V,SMALL(IF('MASTER LIST'!$N:$N=$C$2,ROW('MASTER LIST'!$N:$N),""),ROWS(X$5:X16))),"")} | Y16: {=IFERROR(INDEX('MASTER LIST'!W:W,SMALL(IF('MASTER LIST'!$N:$N=$C$2,ROW('MASTER LIST'!$N:$N),""),ROWS(Y$5:Y16))),"")}
... B25: {=IFERROR(INDEX('MASTER LIST'!B:B,SMALL(IF('MASTER LIST'!$N:$N=$C$2,ROW('MASTER LIST'!$N:$N),""),ROWS(B$5:B25))),"")} | C25: {=IFERROR(INDEX('MASTER LIST'!C:C,SMALL(IF('MASTER LIST'!$N:$N=$C$2,ROW('MASTER LIST'!$N:$N),""),ROWS(C$5:C25))),"")} | D25: {=IFERROR(INDEX('MASTER LIST'!D:D,SMALL(IF('MASTER LIST'!$N:$N=$C$2,ROW('MASTER LIST'!$N:$N),""),ROWS(D$5:D25))),"")} | E25: {=IFERROR(INDEX('MASTER LIST'!E:E,SMALL(IF('MASTER LIST'!$N:$N=$C$2,ROW('MASTER LIST'!$N:$N),""),ROWS(E$5:E25))),"")} | F25: {=IFERROR(INDEX('MASTER LIST'!G:G,SMALL(IF('MASTER LIST'!$N:$N=$C$2,ROW('MASTER LIST'!$N:$N),""),ROWS(F$5:F25))),"")} | G25: {=IFERROR(INDEX('MASTER LIST'!H:H,SMALL(IF('MASTER LIST'!$N:$N=$C$2,ROW('MASTER LIST'!$N:$N),""),ROWS(G$5:G25))),"")} | H25: {=IFERROR(INDEX('MASTER LIST'!I:I,SMALL(IF('MASTER LIST'!$N:$N=$C$2,ROW('MASTER LIST'!$N:$N),""),ROWS(H$5:H25))),"")} | I25: {=IFERROR(INDEX('MASTER LIST'!J:J,SMALL(IF('MASTER LIST'!$N:$N=$C$2,ROW('MASTER LIST'!$N:$N),""),ROWS(I$5:I25))),"")} | J25: {=IFERROR(INDEX('MASTER LIST'!K:K,SMALL(IF('MASTER LIST'!$N:$N=$C$2,ROW('MASTER LIST'!$N:$N),""),ROWS(J$5:J25))),"")} | K25: {=IFERROR(INDEX('MASTER LIST'!L:L,SMALL(IF('MASTER LIST'!$N:$N=$C$2,ROW('MASTER LIST'!$N:$N),""),ROWS(K$5:K25))),"")} | L25: {=IFERROR(INDEX('MASTER LIST'!M:M,SMALL(IF('MASTER LIST'!$N:$N=$C$2,ROW('MASTER LIST'!$N:$N),""),ROWS(L$5:L25))),"")} | M25: {=IFERROR(INDEX('MASTER LIST'!N:N,SMALL(IF('MASTER LIST'!$N:$N=$C$2,ROW('MASTER LIST'!$N:$N),""),ROWS(M$5:M25))),"")} | N25: {=IFERROR(INDEX('MASTER LIST'!P:P,SMALL(IF('MASTER LIST'!$N:$N=$C$2,ROW('MASTER LIST'!$N:$N),""),ROWS(N$5:N25))),"")} | O25: {=IFERROR(INDEX('MASTER LIST'!Q:Q,SMALL(IF('MASTER LIST'!$N:$N=$C$2,ROW('MASTER LIST'!$N:$N),""),ROWS(O$5:O25))),"")} | P25: {=IFERROR(INDEX('MASTER LIST'!#REF!,SMALL(IF('MASTER LIST'!$N:$N=$C$2,ROW('MASTER LIST'!$N:$N),""),ROWS(P$5:P25))),"")} | Q25: {=IFERROR(INDEX('MASTER LIST'!R:R,SMALL(IF('MASTER LIST'!$N:$N=$C$2,ROW('MASTER LIST'!$N:$N),""),ROWS(Q$5:Q25))),"")} | R25: {=IFERROR(INDEX('MASTER LIST'!#REF!,SMALL(IF('MASTER LIST'!$N:$N=$C$2,ROW('MASTER LIST'!$N:$N),""),ROWS(R$5:R25))),"")} | S25: {=IFERROR(INDEX('MASTER LIST'!#REF!,SMALL(IF('MASTER LIST'!$N:$N=$C$2,ROW('MASTER LIST'!$N:$N),""),ROWS(S$5:S25))),"")} | T25: {=IFERROR(INDEX('MASTER LIST'!#REF!,SMALL(IF('MASTER LIST'!$N:$N=$C$2,ROW('MASTER LIST'!$N:$N),""),ROWS(T$5:T25))),"")} | U25: {=IFERROR(INDEX('MASTER LIST'!S:S,SMALL(IF('MASTER LIST'!$N:$N=$C$2,ROW('MASTER LIST'!$N:$N),""),ROWS(U$5:U25))),"")} | V25: {=IFERROR(INDEX('MASTER LIST'!T:T,SMALL(IF('MASTER LIST'!$N:$N=$C$2,ROW('MASTER LIST'!$N:$N),""),ROWS(V$5:V25))),"")} | W25: {=IFERROR(INDEX('MASTER LIST'!U:U,SMALL(IF('MASTER LIST'!$N:$N=$C$2,ROW('MASTER LIST'!$N:$N),""),ROWS(W$5:W25))),"")} | X25: {=IFERROR(INDEX('MASTER LIST'!V:V,SMALL(IF('MASTER LIST'!$N:$N=$C$2,ROW('MASTER LIST'!$N:$N),""),ROWS(X$5:X25))),"")} | Y25: {=IFERROR(INDEX('MASTER LIST'!W:W,SMALL(IF('MASTER LIST'!$N:$N=$C$2,ROW('MASTER LIST'!$N:$N),""),ROWS(Y$5:Y25))),"")}

Sheet MASTER LIST
R1: DOCUMENTATION FROM MANUFACTURER | T1: requested shipped received approved
A3: DAYS TO SUBMIT | B3: PPAP Number | C3: PPAP Req'd by Customer | D3: Current Status | E3: PPAP/IMDS from | F3: C_ID | G3: CUSTOMER | H3: Country | I3: Customer PN | J3: ET Model | K3: Manufacturer | L3: ET Dwg | M3: Rev | N3: ET PN | P3: Description | Q3: IMDS number | R3: PPAP docs | S3: Level | T3: PPAP samples status | U3: Reason of Submission | V3: Sent to Customer | W3: PSW returned from Cust Signed | X3: Origin from report | Y3: Comments | Z3: INSPECTION REPORT NUMBER
A4: =IF(V4="",(TODAY()-C4),(V4-C4)) -> 42115 | B4: PP00001-1 | C4: 2021 | D4: Program died | E4: VEN025 | G4: Gentherm | H4: Mexico | I4: 18052000A | J4: ET36 | K4: =IF(E4="KTG","KTG",(VLOOKUP(J4,'list of outsource'!B:H,2,0))) -> #N/A | L4: D000017 | N4: P000035 | P4: ET36 SWN090-40PVV000, 4.6-800m Black | S4: 2 | V4: 44136
A5: =IF(V5="",(TODAY()-C5),(V5-C5)) -> 42114 | B5: PP00001-1 | C5: 2022 | D5: Program died | E5: VEN025 | G5: Gentherm | H5: Mexico | I5: 18052000A | J5: ET36 | K5: =IF(E5="KTG","KTG",(VLOOKUP(J5,'list of outsource'!B:H,2,0))) -> #N/A | L5: D000017 | N5: P000035 | P5: ET36 SWN090-40PVV000, 4.6-800m Black | S5: 2 | V5: 44136
A6: =IF(V6="",(TODAY()-C6),(V6-C6)) -> 42115 | B6: PP00001-2 | C6: 2021 | D6: Program died | E6: VEN025 | G6: Gentherm | H6: Mexico | I6: 18052001A | J6: ET36 | K6: =IF(E6="KTG","KTG",(VLOOKUP(J6,'list of outsource'!B:H,2,0))) -> #N/A | L6: D000017 | N6: P000036 | P6: ET36 SWN090-40PVV000, 5.1-500m Black | S6: 2 | V6: 44136
A7: =IF(V7="",(TODAY()-C7),(V7-C7)) -> 42114 | B7: PP00001-2 | C7: 2022 | D7: Program died | E7: VEN025 | G7: Gentherm | H7: Mexico | I7: 18052001A | J7: ET36 | K7: =IF(E7="KTG","KTG",(VLOOKUP(J7,'list of outsource'!B:H,2,0))) -> #N/A | L7: D000017 | N7: P000036 | P7: ET36 SWN090-40PVV000, 5.1-500m Black | S7: 2 | V7: 44136
A8: =IF(V8="",(TODAY()-C8),(V8-C8)) -> 42115 | B8: PP00001-3 | C8: 2021 | D8: Program died | E8: VEN025 | G8: Gentherm | H8: Mexico | I8: 12000051A | J8: ET36 | K8: =IF(E8="KTG","KTG",(VLOOKUP(J8,'list of outsource'!B:H,2,0))) -> #N/A | L8: D000017 | N8: P000037 | P8: ET36 SWN090-40PVV000, 6.0-400m Black | S8: 2 | V8: 44136
A9: =IF(V9="",(TODAY()-C9),(V9-C9)) -> 42114 | B9: PP00001-3 | C9: 2022 | D9: Program died | E9: VEN025 | G9: Gentherm | H9: Mexico | I9: 12000051A | J9: ET36 | K9: =IF(E9="KTG","KTG",(VLOOKUP(J9,'list of outsource'!B:H,2,0))) -> #N/A | L9: D000017 | N9: P000037 | P9: ET36 SWN090-40PVV000, 6.0-400m Black | S9: 2 | V9: 44136
A10: =IF(V10="",(TODAY()-C10),(V10-C10)) -> 42115 | B10: PP00001-4 | C10: 2021 | D10: Program died | E10: VEN025 | G10: Gentherm | H10: Mexico | I10: 18052002A | J10: ET36 | K10: =IF(E10="KTG","KTG",(VLOOKUP(J10,'list of outsource'!B:H,2,0))) -> #N/A | L10: D000017 | N10: P000038 | P10: ET36 SWN090-40PVV000, 6.1-500m Black | S10: 2 | V10: 44136
A11: =IF(V11="",(TODAY()-C11),(V11-C11)) -> 42114 | B11: PP00001-4 | C11: 2022 | D11: Program died | E11: VEN025 | G11: Gentherm | H11: Mexico | I11: 18052002A | J11: ET36 | K11: =IF(E11="KTG","KTG",(VLOOKUP(J11,'list of outsource'!B:H,2,0))) -> #N/A | L11: D000017 | N11: P000038 | P11: ET36 SWN090-40PVV000, 6.1-500m Black | S11: 2 | V11: 44136
A12: =IF(V12="",(TODAY()-C12),(V12-C12)) -> 42115 | B12: PP00001-5 | C12: 2021 | D12: Program died | E12: VEN025 | G12: Gentherm | H12: Mexico | I12: 12002514A | J12: ET36 | K12: =IF(E12="KTG","KTG",(VLOOKUP(J12,'list of outsource'!B:H,2,0))) -> #N/A | L12: D000017 | N12: P000040 | P12: ET36 SWN090-40PVV000,7.0-340m Black | S12: 2 | V12: 44136
A13: =IF(V13="",(TODAY()-C13),(V13-C13)) -> 42114 | B13: PP00001-5 | C13: 2022 | D13: Program died | E13: VEN025 | G13: Gentherm | H13: Mexico | I13: 12002514A | J13: ET36 | K13: =IF(E13="KTG","KTG",(VLOOKUP(J13,'list of outsource'!B:H,2,0))) -> #N/A | L13: D000017 | N13: P000040 | P13: ET36 SWN090-40PVV000,7.0-340m Black | S13: 2 | V13: 44136
A14: =IF(V14="",(TODAY()-C14),(V14-C14)) -> 42115 | B14: PP00001-6 | C14: 2021 | D14: Program died | E14: VEN025 | G14: Gentherm | H14: Mexico | I14: 18052065A | J14: ET36 | K14: =IF(E14="KTG","KTG",(VLOOKUP(J14,'list of outsource'!B:H,2,0))) -> #N/A | L14: D000017 | N14: P000039 | P14: ET36 SWN090-40PVV000,7.1-350m Black | S14: 2 | V14: 44136
A15: =IF(V15="",(TODAY()-C15),(V15-C15)) -> 42114 | B15: PP00001-6 | C15: 2022 | D15: Program died | E15: VEN025 | G15: Gentherm | H15: Mexico | I15: 18052065A | J15: ET36 | K15: =IF(E15="KTG","KTG",(VLOOKUP(J15,'list of outsource'!B:H,2,0))) -> #N/A | L15: D000017 | N15: P000039 | P15: ET36 SWN090-40PVV000,7.1-350m Black | S15: 2 | V15: 44136
... A17: =IF(V17="",(TODAY()-C17),(V17-C17)) -> 42114 | B17: PP00001-7 | C17: 2022 | D17: Program died | E17: VEN025 | G17: Gentherm | H17: Mexico | I17: 12001469A | J17: ET36 | K17: =IF(E17="KTG","KTG",(VLOOKUP(J17,'list of outsource'!B:H,2,0))) -> #N/A | L17: D000017 | N17: P000041 | P17: ET36 SWN090-40PVV000, 10.0-150m Black | S17: 2 | V17: 44136
A18: =IF(V18="",(TODAY()-C18),(V18-C18)) -> 102 | B18: PP00029-01 | C18: 44879 | D18: PSW Pending Approve | E18: VEN329 | F18: 5123 | G18: Angstrom | H18: Mexico | I18: ET25-18.3/4.5-BLK-40mm | J18: ET25 | K18: =IF(E18="KTG","KTG",(VLOOKUP(J18,'list of outsource'!B:H,2,0))) -> ETC | L18: D000060 | N18: P000252 | O18: CUS696 | P18: ET25-18.3/4.5-BLK-40mm | Q18: 1198485921 | S18: 2 | U18: Initial Submission | V18: 44981
A19: =IF(V19="",(TODAY()-C19),(V19-C19)) -> 102 | B19: PP00029-03 | C19: 44879 | D19: PSW Pending Approve | E19: VEN329 | F19: 5124 | G19: Angstrom | H19: Mexico | I19: ET25-18.3/4.5-BLK-65mm | J19: ET25 | K19: =IF(E19="KTG","KTG",(VLOOKUP(J19,'list of outsource'!B:H,2,0))) -> ETC | L19: D000060 | N19: P000254 | O19: CUS696 | P19: ET25-18.3/4.5-BLK-65mm | Q19: 1199854155 | S19: 2 | U19: Initial Submission | V19: 44981
A20: =IF(V20="",(TODAY()-C20),(V20-C20)) -> 102 | B20: PP00029-04 | C20: 44879 | D20: PSW Pending Approve | E20: VEN329 | F20: 5125 | G20: Angstrom | H20: Mexico | I20: ET25-18.3/4.5-BLK-50mm | J20: ET25 | K20: =IF(E20="KTG","KTG",(VLOOKUP(J20,'list of outsource'!B:H,2,0))) -> ETC | L20: D000060 | N20: P000253 | O20: CUS696 | P20: ET25-18.3/4.5-BLK-50mm | Q20: 1199292910 | S20: 2 | U20: Initial Submission | V20: 44981
A21: =IF(V21="",(TODAY()-C21),(V21-C21)) -> 102 | B21: PP00029-06 | C21: 44879 | D21: PSW Pending Approve | E21: VEN329 | F21: 5126 | G21: Angstrom | H21: Mexico | I21: ET25-24.0/6.0-BLK-60mm | J21: ET25 | K21: =IF(E21="KTG","KTG",(VLOOKUP(J21,'list of outsource'!B:H,2,0))) -> ETC | L21: D000060 | N21: P000277 | O21: CUS696 | P21: ET25-24.0/6.0-BLK-60mm | Q21: 1196335819 | S21: 2 | U21: Initial Submission | V21: 44981
A22: =IF(V22="",(TODAY()-C22),(V22-C22)) -> 41976 | B22: PP00003-1 | C22: 2021 | D22: Approved 2020 | E22: VEN025 | F22: 104 | G22: Nexans | H22: Mexico | I22: 95850329 | J22: RO | K22: =IF(E22="KTG","KTG",(VLOOKUP(J22,'list of outsource'!B:H,2,0))) -> #N/A | L22: RO 001 | N22: E101702 | P22: CYG-DWT-RO(4005)-5.75-BK-75 | S22: 4 | U22: Initial Submission | V22: 43997 | W22: 44067
A23: =IF(V23="",(TODAY()-C23),(V23-C23)) -> 41975 | B23: PP00003-1 | C23: 2022 | D23: Approved 2020 | E23: VEN025 | F23: 104 | G23: Nexans | H23: Mexico | I23: 95850329 | J23: RO | K23: =IF(E23="KTG","KTG",(VLOOKUP(J23,'list of outsource'!B:H,2,0))) -> #N/A | L23: RO 001 | P23: CYG-DWT-RO(4005)-5.75-BK-75 | S23: 4 | U23: Initial Submission | V23: 43997 | W23: 44067
A24: =IF(V24="",(TODAY()-C24),(V24-C24)) -> 41976 | B24: PP00003-2 | C24: 2021 | D24: Approved 2020 | E24: VEN025 | F24: 107 | G24: Nexans | H24: Mexico | I24: 95850330 | J24: RO | K24: =IF(E24="KTG","KTG",(VLOOKUP(J24,'list of outsource'!B:H,2,0))) -> #N/A | L24: RO 001 | N24: E101705 | P24: CYG-DWT-RO(4005)-7.4-BK-75 | S24: 4 | U24: Initial Submission | V24: 43997 | W24: 44067
A25: =IF(V25="",(TODAY()-C25),(V25-C25)) -> 41975 | B25: PP00003-2 | C25: 2022 | D25: Approved 2020 | E25: VEN025 | F25: 107 | G25: Nexans | H25: Mexico | I25: 95850330 | J25: RO | K25: =IF(E25="KTG","KTG",(VLOOKUP(J25,'list of outsource'!B:H,2,0))) -> #N/A | L25: RO 001 | P25: CYG-DWT-RO(4005)-7.4-BK-75 | S25: 4 | U25: Initial Submission | V25: 43997 | W25: 44067
A26: =IF(V26="",(TODAY()-C26),(V26-C26)) -> 41976 | B26: PP00003-3 | C26: 2021 | D26: Approved 2020 | E26: VEN025 | F26: 108 | G26: Nexans | H26: Mexico | I26: 95850331 | J26: RO | K26: =IF(E26="KTG","KTG",(VLOOKUP(J26,'list of outsource'!B:H,2,0))) -> #N/A | L26: RO 001 | N26: E101706 | P26: CYG-DWT-RO(4005)-11.0-BK-75 | S26: 4 | U26: Initial Submission | V26: 43997 | W26: 44067
A27: =IF(V27="",(TODAY()-C27),(V27-C27)) -> 41975 | B27: PP00003-3 | C27: 2022 | D27: Approved 2020 | E27: VEN025 | F27: 108 | G27: Nexans | H27: Mexico | I27: 95850331 | J27: RO | K27: =IF(E27="KTG","KTG",(VLOOKUP(J27,'list of outsource'!B:H,2,0))) -> #N/A | L27: RO 001 | P27: CYG-DWT-RO(4005)-11.0-BK-75 | S27: 4 | U27: Initial Submission | V27: 43997 | W27: 44067
A28: =IF(V28="",(TODAY()-C28),(V28-C28)) -> 41976 | B28: PP00003-4 | C28: 2021 | D28: Approved 2020 | E28: VEN025 | F28: 105 | G28: Nexans | H28: Mexico | I28: 95850332 | J28: RO | K28: =IF(E28="KTG","KTG",(VLOOKUP(J28,'list of outsource'!B:H,2,0))) -> #N/A | L28: RO 001 | N28: E101703 | P28: CYG-DWT-RO(4005)-18.3-BK-75 | S28: 4 | U28: Initial Submission | V28: 43997 | W28: 44067
A29: =IF(V29="",(TODAY()-C29),(V29-C29)) -> 41975 | B29: PP00003-4 | C29: 2022 | D29: Approved 2020 | E29: VEN025 | F29: 105 | G29: Nexans | H29: Mexico | I29: 95850332 | J29: RO | K29: =IF(E29="KTG","KTG",(VLOOKUP(J29,'list of outsource'!B:H,2,0))) -> #N/A | L29: RO 001 | P29: CYG-DWT-RO(4005)-18.3-BK-75 | S29: 4 | U29: Initial Submission | V29: 43997 | W29: 44067
A30: =IF(V30="",(TODAY()-C30),(V30-C30)) -> 41976 | B30: PP00003-5 | C30: 2021 | D30: Approved 2020 | E30: VEN025 | F30: 103 | G30: Nexans | H30: Mexico | I30: 95850007 | J30: RO | K30: =IF(E30="KTG","KTG",(VLOOKUP(J30,'list of outsource'!B:H,2,0))) -> #N/A | L30: RO 001 | N30: E101701 | P30: CYG-DWT-RO(4005)-18.3-BK-150 | S30: 4 | U30: Initial Submission | V30: 43997 | W30: 44067
A31: =IF(V31="",(TODAY()-C31),(V31-C31)) -> 41975 | B31: PP00003-5 | C31: 2022 | D31: Approved 2020 | E31: VEN025 | F31: 103 | G31: Nexans | H31: Mexico | I31: 95850007 | J31: RO | K31: =IF(E31="KTG","KTG",(VLOOKUP(J31,'list of outsource'!B:H,2,0))) -> #N/A | L31: RO 001 | P31: CYG-DWT-RO(4005)-18.3-BK-150 | S31: 4 | U31: Initial Submission | V31: 43997 | W31: 44067
A32: =IF(V32="",(TODAY()-C32),(V32-C32)) -> 102 | B32: PP00029-07 | C32: 44879 | D32: PSW Pending Approve | E32: VEN329 | F32: 5127 | G32: Angstrom | H32: Mexico | I32: ET25-7.4/1.7-BLK-50mm | J32: ET25 | K32: =IF(E32="KTG","KTG",(VLOOKUP(J32,'list of outsource'!B:H,2,0))) -> ETC | L32: D000060 | N32: P000293 | O32: CUS696 | P32: ET25-7.4/1.7-BLK-50mm | Q32: 1199295023 | S32: 2 | U32: Initial Submission | V32: 44981
A33: =IF(V33="",(TODAY()-C33),(V33-C33)) -> 102 | B33: PP00029-08 | C33: 44879 | D33: PSW Pending Approve | E33: VEN329 | F33: 5128 | G33: Angstrom | H33: Mexico | I33: ET87-17.8/4.4-BLK-50mm | J33: ET87 | K33: =IF(E33="KTG","KTG",(VLOOKUP(J33,'list of outsource'!B:H,2,0))) -> ETC | L33: D000073 | N33: P000235 | O33: CUS696 | P33: ET87-17.8/4.4-BLK-50mm | Q33: 1199871420 | S33: 2 | U33: Initial Submission | V33: 44981
A34: =IF(V34="",(TODAY()-C34),(V34-C34)) -> 102 | B34: PP00029-09 | C34: 44879 | D34: PSW Pending Approve | E34: VEN329 | F34: 5129 | G34: Angstrom | H34: Mexico | I34: ET25-5.7/1.3-BLK-50mm | J34: ET25 | K34: =IF(E34="KTG","KTG",(VLOOKUP(J34,'list of outsource'!B:H,2,0))) -> ETC | L34: D000060 | N34: P000204 | O34: CUS696 | P34: ET25-5.7/1.3-50mm-BLK | Q34: 1196335595 | S34: 2 | U34: Initial Submission | V34: 44981
A35: =IF(V35="",(TODAY()-C35),(V35-C35)) -> 102 | B35: PP00029-10 | C35: 44879 | D35: PSW Pending Approve | E35: VEN329 | F35: 5130 | G35: Angstrom | H35: Mexico | I35: ET87-17.8/4.4-BLK-40mm | J35: ET87 | K35: =IF(E35="KTG","KTG",(VLOOKUP(J35,'list of outsource'!B:H,2,0))) -> ETC | L35: D000073 | N35: P000382 | O35: CUS696 | P35: ET87-17.8/4.4-BLK-40mm | Q35: 1199874872 | S35: 2 | U35: Initial Submission | V35: 44981
A36: =IF(V36="",(TODAY()-C36),(V36-C36)) -> 34 | B36: PP00029-12 | C36: 44995 | D36: Approved 2023 | E36: VEN329 | F36: 5131 | G36: Angstrom | H36: Mexico | I36: ET25-18.3/4.5-BLK-145MM | J36: ET25 | K36: =IF(E36="KTG","KTG",(VLOOKUP(J36,'list of outsource'!B:H,2,0))) -> ETC | L36: D000060 | N36: P000325 | O36: CUS696 | P36: ET25-18.3/4.5-BLK-145MM | Q36: 1212621816 | S36: 4 | U36: Initial Submission | V36: 13-Apr-23 | W36: 18-Apr-23
A37: =IF(V37="",(TODAY()-C37),(V37-C37)) -> 34 | B37: PP00029-13 | C37: 44995 | D37: Approved 2023 | E37: VEN329 | F37: 5132 | G37: Angstrom | H37: Mexico | I37: ET25-18.3/4.5-BLK-180MM | J37: ET25 | K37: =IF(E37="KTG","KTG",(VLOOKUP(J37,'list of outsource'!B:H,2,0))) -> ETC | L37: D000060 | N37: P000326 | O37: CUS696 | P37: ET25-18.3/4.5-BLK-180MM | Q37: 1212622204 | S37: 4 | U37: Initial Submission | V37: 13-Apr-23 | W37: 18-Apr-23
A38: =IF(V38="",(TODAY()-C38),(V38-C38)) -> 34 | B38: PP00029-14 | C38: 44995 | D38: Approved 2023 | E38: VEN329 | F38: 5133 | G38: Angstrom | H38: Mexico | I38: ET25-18.3/4.5-BLK-245MM | J38: ET25 | K38: =IF(E38="KTG","KTG",(VLOOKUP(J38,'list of outsource'!B:H,2,0))) -> ETC | L38: D000060 | N38: P000327 | O38: CUS696 | P38: ET25-18.3/4.5-BLK-245MM | Q38: 1212622233 | S38: 4 | U38: Initial Submission | V38: 13-Apr-23 | W38: 18-Apr-23
A39: =IF(V39="",(TODAY()-C39),(V39-C39)) -> 36 | B39: PP00029-16 | C39: 45538 | D39: PSW Pending Approve | E39: VEN329 | F39: 5134 | G39: Angstrom | H39: Mexico | I39: ET25-18.3/4.5-BLK-110mm | J39: ET25 | K39: =IF(E39="KTG","KTG",(VLOOKUP(J39,'list of outsource'!B:H,2,0))) -> ETC | L39: D000060 | M39: 63 | N39: P000693 | O39: CUS696 | P39: ET25-18.3/4.5-BLK-110mm | Q39: 1358903619 / 1 | R39: 45544 | S39: 4 | T39: requested | U39: Initial Submission | V39: 45574 | Z39: #N/A
A40: =IF(V40="",(TODAY()-C40),(V40-C40)) -> 0 | B40: PP00029-17 | C40: 45790 | D40: Approved 2023 | E40: VEN025 | F40: 5135 | G40: Angstrom | H40: Mexico | I40: DWT(VTS) #4-40mm | K40: =IF(E40="KTG","KTG",(VLOOKUP(J40,'list of outsource'!B:H,2,0))) -> #N/A | N40: E69612 | O40: CUS696 | P40: CYG-DWT(VTS), 4:1 SHRINK RATIO, 17.8 ID BLK 40MM | S40: 4 | T40: n/a | U40: Initial Submission | V40: 45790 | W40: 45217 | X40: ** | Z40: #N/A
A41: =IF(V41="",(TODAY()-C41),(V41-C41)) -> 22 | B41: PP00029-18 | C41: 45852 | D41: PPAP received, pending to review files | E41: VEN025 | F41: 5136 | G41: Angstrom | H41: Mexico | I41: DWT(RO) #4-40mm | K41: =IF(E41="KTG","KTG",(VLOOKUP(J41,'list of outsource'!B:H,2,0))) -> #N/A | N41: E69601 | O41: CUS696 | P41: DWT(RO) 4:1 SHRINK RATIO, 17.80 ID, BK, 40mm LENGTH | S41: 4 | T41: n/a | U41: Annual validation | V41: 45874 | X41: ** | Z41: #N/A
A42: =IF(V42="",(TODAY()-C42),(V42-C42)) -> 41 | B42: PP00042-0001 | C42: 45097 | D42: Approved 2023 | E42: VEN329 | F42: 5137 | G42: Aptiv | H42: Mexico | I42: 35758280 | J42: ET86 | K42: =IF(E42="KTG","KTG",(VLOOKUP(J42,'list of outsource'!B:H,2,0))) -> ETC | L42: D000064 | M42: 4 | N42: P000554 | O42: CUS1098 | P42: ET86-9.0/2.3-BLK-30MM | Q42: 1242955812 | R42: ok | S42: 2 | U42: Initial Submission | V42: 45138 | W42: 45268
...

Sheet CODES OF CUSTOMERS
B1: PPAP Number | C1: CUSTOMER | D1: Country | E1: Last
B2: PP00046 | C2: ACS | D2: Mexico | E2: 0005
B3: PP00076 | C3: Amphenol FCI/TCS | D3: Mexico | E3: 0005
B4: PP00029 | C4: Angstrom | D4: Mexico | E4: 0002
B5: PP00042 | C5: Aptiv | D5: Mexico | E5: 0027
B6: PP00063 | C6: Aptiv | D6: EU | E6: 0005
B7: PP00031 | C7: AQ Wiring Systems UAB | D7: Europe | E7: 0068
B8: PP00045 | C8: Autokabel | D8: Mexico | E8: 0040
B9: PP00033 | C9: Bizlink | E9: 0095
B10: PP00065 | C10: Brose | D10: Germany | E10: 0020
B11: PP00012 | C11: CEMM | D11: Mexico | E11: 0035
B12: PP00058 | C12: COFAT | D12: Mexico | E12: 0009
B13: PP00034 | C13: Condumex | D13: Mexico | E13: 0038
B14: PP00077 | C14: Cooper Standard | D14: EU | E14: 0009
B15: PP00078 | C15: CTS | D15: EU | E15: 0049
B16: PP00079 | C16: Curt Group | D16: Mexico | E16: 0001
B17: PP00037 | C17: CVG | D17: Mexico | E17: 0032
B18: PP00080 | C18: Dortec Industries | D18: EU | E18: 0009
B19: PP00069 | C19: Draexlmaier | D19: Mexico | E19: 0004
B20: PP00081 | C20: E&K | D20: EU | E20: 0001
B21: PP00036 | C21: ECI | D21: Mexico | E21: 0001
... B31: PP00030 | C31: Flextronics | D31: Mexico | E31: 0004
B32: PP00070 | C32: Flextronics AGM | D32: Costa Rica
B33: PP00085 | C33: Fraenkishe | D33: EU
B34: PP00023 | C34: Gentherm | D34: Germany | E34: 0012
B35: PP00086 | C35: GG Cables & Wires | D35: Mexico | E35: 0003
B36: PP00060 | C36: Hesto | D36: EU | E36: 0032
B37: PP00087 | C37: Huf | D37: Mexico | E37: 0016
B38: PP00088 | C38: Hutchinson | D38: Mexico | E38: 0004
B39: PP00057 | C39: Intercable | D39: EU | E39: 0007
B40: PP00089 | C40: Intercomp | D40: EU | E40: 0012
B41: PP00090 | C41: Julian Electric | D41: Mexico | E41: 0034
B42: PP00091 | C42: Kalas Manufacturing | D42: EU | E42: 0015
B43: PP00092 | C43: Kent Manufacturing | D43: EU | E43: 0004
B44: PP00093 | C44: Kongsberg | D44: Mexico | E44: 0003
B45: PP00048 | C45: Kostal | D45: Germany | E45: 0004
... B89: PP00051 | C89: Yazaki Europe | D89: EU | E89: 0001

Sheet list of outsource
G3: Ellaborated by: | H3: Frank Du
G4: Revision: | H4: 01
G5: Date of revision: | H5: 46000
B7: Model | C7: Name of Manufacturer | D7: Manufacturer location | E7: Proximity to Manufacturer from ETC (car travel) | F7: Type of certificate ISO 9001, IATF16949 or both | G7: Expiration date of certificate (YYYY-MM-DD) | H7: Date of last audit to supplier by ETC (YYYY-MM-DD)
B8: ET01 | C8: ETC design and Kebao manufacture | D8: Guangzhou | E8: 16hr | F8: IATF 16949 | G8: 46343 | H8: /
B9: ET05 | C9: ETC | D9: Taicang | E9: - | F9: IATF 16949 | G9: 47020 | H9: N/A
B10: ET25 | C10: ETC | D10: Taicang | E10: - | F10: IATF 16949 | G10: 47020 | H10: N/A
B11: ET26 | C11: ETC | D11: Taicang | E11: - | F11: IATF 16949 | G11: 47020 | H11: N/A
B12: ET27 | C12: ETC | D12: Taicang | E12: - | F12: IATF 16949 | G12: 47020 | H12: N/A
B13: ET28 | C13: ETC | D13: Taicang | E13: - | F13: IATF 16949 | G13: 47020 | H13: N/A
B14: ET42 | C14: ETC | D14: Taicang | E14: - | F14: IATF 16949 | G14: 47020 | H14: N/A
B15: ET43 | C15: ETC | D15: Taicang | E15: - | F15: IATF 16949 | G15: 47020 | H15: N/A
B16: ET44 | C16: ETC | D16: Taicang | E16: - | F16: IATF 16949 | G16: 47020 | H16: N/A
B17: ET45 | C17: ETC | D17: Taicang | E17: - | F17: IATF 16949 | G17: 47020 | H17: N/A
B18: ET46 | C18: ETC | D18: Taicang | E18: - | F18: IATF 16949 | G18: 47020 | H18: N/A
B19: ET47 | C19: ETC | D19: Taicang | E19: - | F19: IATF 16949 | G19: 47020 | H19: N/A
... B51: ET89 | C51: Hongjing (Grandview) | D51: Dongguan | E51: 16 hrs | F51: ISO 9001 PLAN end of 2024 for IATF16949 and MES system | G51: 46268 | H51: visit at 2024/8/9 move to a new location about 20,000 ㎡ from 2024/8/1 hard to audit.
B52: ET92 | C52: Dongguan Gendian New Materials Co. , Ltd. | F52: IATF 16949 | G52: 46170 | H52: /
B53: ET93 | C53: Dongguan Gendian New Materials Co. , Ltd. | F53: IATF 16949 | G53: 46170 | H53: /
B54: ET55 | C54: Guangzhou yilian electronic Co. , Ltd. | D54: Guangzhou | E54: 16 hrs | F54: IATF 16949 | G54: 46197 | H54: /
B55: ET56 | C55: Guangzhou yilian electronic Co. , Ltd. | D55: Guangzhou | E55: 16 hrs | F55: IATF 16949 | G55: 46197 | H55: /
B56: ET00 | C56: Woer | D56: Shenzhen, China | G56: 46614
B57: ET22 | C57: UPM | G57: 46614
B58: ET01 | C58: UPM | G58: 46614
B59: ET02 | C59: UPM | G59: 46614
B60: ET04 | C60: UPM | G60: 46614
B61: ET06 | C61: UPM | G61: 46614
B62: ET07 | C62: Woer | D62: Shenzhen, China | G62: 46614
B63: ET08 | C63: UPM | G63: 46614
B64: ET09 | C64: UPM | G64: 46614
B65: ET10 | C65: UPM | G65: 46614
B66: ET11 | C66: UPM | G66: 46614
B67: ET12 | C67: UPM | G67: 46614
B68: ET14 | C68: UPM | G68: 46614
B69: ET15 | C69: UPM | G69: 46614
B70: ET16 | C70: UPM | G70: 46614
B71: ET17 | C71: UPM | G71: 46614
B72: ET18 | C72: UPM | G72: 46614
B73: ET20 | C73: UPM | G73: 46614
B74: ET21 | C74: UPM | G74: 46614
...
