Workbook

Sheet Hoja1
A1: DAYS TO SUBMIT | B1: PPAP Number | C1: PPAP Req'd by Customer | D1: Current Status | E1: PPAP/IMDS from | F1: CUSTOMER | G1: Country | H1: Customer PN | I1: ET Model | J1: Manufacturer | K1: ET Dwg | L1: Rev | M1: ET PN | N1: Description | O1: IMDS number | P1: IMDS Status | Q1: PPAP docs | R1: Run@Rate | S1: Packing spec | T1: Feasibility report | U1: Level | V1: PPAP samples status | W1: Reason of Submission | X1: Sent to Customer | Y1: PSW returned from Cust Signed | Z1: Origin from report | AA1: Comments | AB1: INSPECTION REPORT NUMBER | AE1: ET PN en NetSuite | AF1: Si estan en la BD | AG1: PPAP Number | AH1: Customer_PN_ID | AI1: Customer_PN | AJ1: Cust PN Coinciden
A2: =IF(X2="",(TODAY()-C2),(X2-C2)) -> 5451 | B2: PP00003-1 | C2: 38546 | D2: Approved 2020 | E2: KTG | F2: Nexans | G2: Mexico | H2: 95850329 | I2: RO | J2: =IF(E2="KTG","KTG",(VLOOKUP(I2,'[1]list of outsource'!B:H,2,0))) -> KTG | K2: RO 001 | M2: E101702 | N2: CYG-DWT-RO(4005)-5.75-BK-75 | U2: 4 | W2: Initial Submission | X2: 43997 | Y2: 44067 | AE2: =LEFT(M2, FIND(" ", M2 & " ") - 1) -> E101702 | AF2: =_xlfn.XLOOKUP(AE2, Hoja2!A:A, Hoja2!A:A) -> E101702 | AG2: =LEFT(B2, FIND(" ", B2 & " ") - 1) -> PP00003-1 | AH2: =_xlfn.XLOOKUP(AG2, Hoja3!A:A, Hoja3!B:B) -> 104 | AI2: =_xlfn.XLOOKUP(AH2, Hoja4!A:A, Hoja4!B:B) -> 95850329 | AJ2: =H2=AI2 -> TRUE
A3: =IF(X3="",(TODAY()-C3),(X3-C3)) -> 5451 | B3: PP00003-2 | C3: 38546 | D3: Approved 2020 | E3: KTG | F3: Nexans | G3: Mexico | H3: 95850330 | I3: RO | J3: =IF(E3="KTG","KTG",(VLOOKUP(I3,'[1]list of outsource'!B:H,2,0))) -> KTG | K3: RO 001 | M3: E101705 | N3: CYG-DWT-RO(4005)-7.4-BK-75 | U3: 4 | W3: Initial Submission | X3: 43997 | Y3: 44067 | AE3: =LEFT(M3, FIND(" ", M3 & " ") - 1) -> E101705 | AF3: =_xlfn.XLOOKUP(AE3, Hoja2!A:A, Hoja2!A:A) -> E101705 | AG3: =LEFT(B3, FIND(" ", B3 & " ") - 1) -> PP00003-2 | AH3: =_xlfn.XLOOKUP(AG3, Hoja3!A:A, Hoja3!B:B) -> 107 | AI3: =_xlfn.XLOOKUP(AH3, Hoja4!A:A, Hoja4!B:B) -> 95850330 | AJ3: =H3=AI3 -> TRUE
A4: =IF(X4="",(TODAY()-C4),(X4-C4)) -> 5451 | B4: PP00003-3 | C4: 38546 | D4: Approved 2020 | E4: KTG | F4: Nexans | G4: Mexico | H4: 95850331 | I4: RO | J4: =IF(E4="KTG","KTG",(VLOOKUP(I4,'[1]list of outsource'!B:H,2,0))) -> KTG | K4: RO 001 | M4: E101706 | N4: CYG-DWT-RO(4005)-11.0-BK-75 | U4: 4 | W4: Initial Submission | X4: 43997 | Y4: 44067 | AE4: =LEFT(M4, FIND(" ", M4 & " ") - 1) -> E101706 | AF4: =_xlfn.XLOOKUP(AE4, Hoja2!A:A, Hoja2!A:A) -> E101706 | AG4: =LEFT(B4, FIND(" ", B4 & " ") - 1) -> PP00003-3 | AH4: =_xlfn.XLOOKUP(AG4, Hoja3!A:A, Hoja3!B:B) -> 108 | AI4: =_xlfn.XLOOKUP(AH4, Hoja4!A:A, Hoja4!B:B) -> 95850331 | AJ4: =H4=AI4 -> TRUE
A5: =IF(X5="",(TODAY()-C5),(X5-C5)) -> 5451 | B5: PP00003-4 | C5: 38546 | D5: Approved 2020 | E5: KTG | F5: Nexans | G5: Mexico | H5: 95850332 | I5: RO | J5: =IF(E5="KTG","KTG",(VLOOKUP(I5,'[1]list of outsource'!B:H,2,0))) -> KTG | K5: RO 001 | M5: E101703 | N5: CYG-DWT-RO(4005)-18.3-BK-75 | U5: 4 | W5: Initial Submission | X5: 43997 | Y5: 44067 | AE5: =LEFT(M5, FIND(" ", M5 & " ") - 1) -> E101703 | AF5: =_xlfn.XLOOKUP(AE5, Hoja2!A:A, Hoja2!A:A) -> E101703 | AG5: =LEFT(B5, FIND(" ", B5 & " ") - 1) -> PP00003-4 | AH5: =_xlfn.XLOOKUP(AG5, Hoja3!A:A, Hoja3!B:B) -> 105 | AI5: =_xlfn.XLOOKUP(AH5, Hoja4!A:A, Hoja4!B:B) -> 95850332 | AJ5: =H5=AI5 -> TRUE
A6: =IF(X6="",(TODAY()-C6),(X6-C6)) -> 5451 | B6: PP00003-5 | C6: 38546 | D6: Approved 2020 | E6: KTG | F6: Nexans | G6: Mexico | H6: 95850007 | I6: RO | J6: =IF(E6="KTG","KTG",(VLOOKUP(I6,'[1]list of outsource'!B:H,2,0))) -> KTG | K6: RO 001 | M6: E101701 | N6: CYG-DWT-RO(4005)-18.3-BK-150 | U6: 4 | W6: Initial Submission | X6: 43997 | Y6: 44067 | AE6: =LEFT(M6, FIND(" ", M6 & " ") - 1) -> E101701 | AF6: =_xlfn.XLOOKUP(AE6, Hoja2!A:A, Hoja2!A:A) -> E101701 | AG6: =LEFT(B6, FIND(" ", B6 & " ") - 1) -> PP00003-5 | AH6: =_xlfn.XLOOKUP(AG6, Hoja3!A:A, Hoja3!B:B) -> 103 | AI6: =_xlfn.XLOOKUP(AH6, Hoja4!A:A, Hoja4!B:B) -> 95850007 | AJ6: =H6=AI6 -> TRUE
A7: =IF(X7="",(TODAY()-C7),(X7-C7)) -> 42115 | B7: PP00001-1 | C7: 2021 | D7: Program died | E7: KTG | F7: Gentherm | G7: Mexico | H7: 18052000A | I7: ET36 | J7: =IF(E7="KTG","KTG",(VLOOKUP(I7,'[1]list of outsource'!B:H,2,0))) -> KTG | K7: D000017 | M7: P000035 | N7: ET36 SWN090-40PVV000, 4.6-800m Black | U7: 2 | X7: 44136 | AE7: =LEFT(M7, FIND(" ", M7 & " ") - 1) -> P000035 | AF7: =_xlfn.XLOOKUP(AE7, Hoja2!A:A, Hoja2!A:A) -> #N/A
A8: =IF(X8="",(TODAY()-C8),(X8-C8)) -> 42115 | B8: PP00001-2 | C8: 2021 | D8: Program died | E8: KTG | F8: Gentherm | G8: Mexico | H8: 18052001A | I8: ET36 | J8: =IF(E8="KTG","KTG",(VLOOKUP(I8,'[1]list of outsource'!B:H,2,0))) -> KTG | K8: D000017 | M8: P000036 | N8: ET36 SWN090-40PVV000, 5.1-500m Black | U8: 2 | X8: 44136 | AE8: =LEFT(M8, FIND(" ", M8 & " ") - 1) -> P000036 | AF8: =_xlfn.XLOOKUP(AE8, Hoja2!A:A, Hoja2!A:A) -> #N/A
A9: =IF(X9="",(TODAY()-C9),(X9-C9)) -> 42115 | B9: PP00001-3 | C9: 2021 | D9: Program died | E9: KTG | F9: Gentherm | G9: Mexico | H9: 12000051A | I9: ET36 | J9: =IF(E9="KTG","KTG",(VLOOKUP(I9,'[1]list of outsource'!B:H,2,0))) -> KTG | K9: D000017 | M9: P000037 | N9: ET36 SWN090-40PVV000, 6.0-400m Black | U9: 2 | X9: 44136 | AE9: =LEFT(M9, FIND(" ", M9 & " ") - 1) -> P000037 | AF9: =_xlfn.XLOOKUP(AE9, Hoja2!A:A, Hoja2!A:A) -> #N/A
A10: =IF(X10="",(TODAY()-C10),(X10-C10)) -> 5590 | B10: PP00001-4 | C10: 38546 | D10: Program died | E10: KTG | F10: Gentherm | G10: Mexico | H10: 18052002A | I10: ET36 | J10: =IF(E10="KTG","KTG",(VLOOKUP(I10,'[1]list of outsource'!B:H,2,0))) -> KTG | K10: D000017 | M10: P000038 | N10: ET36 SWN090-40PVV000, 6.1-500m Black | U10: 2 | X10: 44136 | AE10: =LEFT(M10, FIND(" ", M10 & " ") - 1) -> P000038 | AF10: =_xlfn.XLOOKUP(AE10, Hoja2!A:A, Hoja2!A:A) -> #N/A
A11: =IF(X11="",(TODAY()-C11),(X11-C11)) -> 5590 | B11: PP00001-5 | C11: 38546 | D11: Program died | E11: KTG | F11: Gentherm | G11: Mexico | H11: 12002514A | I11: ET36 | J11: =IF(E11="KTG","KTG",(VLOOKUP(I11,'[1]list of outsource'!B:H,2,0))) -> KTG | K11: D000017 | M11: P000040 | N11: ET36 SWN090-40PVV000,7.0-340m Black | U11: 2 | X11: 44136 | AE11: =LEFT(M11, FIND(" ", M11 & " ") - 1) -> P000040 | AF11: =_xlfn.XLOOKUP(AE11, Hoja2!A:A, Hoja2!A:A) -> #N/A
A12: =IF(X12="",(TODAY()-C12),(X12-C12)) -> 5590 | B12: PP00001-6 | C12: 38546 | D12: Program died | E12: KTG | F12: Gentherm | G12: Mexico | H12: 18052065A | I12: ET36 | J12: =IF(E12="KTG","KTG",(VLOOKUP(I12,'[1]list of outsource'!B:H,2,0))) -> KTG | K12: D000017 | M12: P000039 | N12: ET36 SWN090-40PVV000,7.1-350m Black | U12: 2 | X12: 44136 | AE12: =LEFT(M12, FIND(" ", M12 & " ") - 1) -> P000039 | AF12: =_xlfn.XLOOKUP(AE12, Hoja2!A:A, Hoja2!A:A) -> #N/A
A13: =IF(X13="",(TODAY()-C13),(X13-C13)) -> 5590 | B13: PP00001-7 | C13: 38546 | D13: Program died | E13: KTG | F13: Gentherm | G13: Mexico | H13: 12001469A | I13: ET36 | J13: =IF(E13="KTG","KTG",(VLOOKUP(I13,'[1]list of outsource'!B:H,2,0))) -> KTG | K13: D000017 | M13: P000041 | N13: ET36 SWN090-40PVV000, 10.0-150m Black | U13: 2 | X13: 44136 | AE13: =LEFT(M13, FIND(" ", M13 & " ") - 1) -> P000041 | AF13: =_xlfn.XLOOKUP(AE13, Hoja2!A:A, Hoja2!A:A) -> #N/A
A14: =IF(X14="",(TODAY()-C14),(X14-C14)) -> 5498 | B14: PP00002-1 | C14: 38546 | E14: UPM | F14: Lear | G14: Morocco | H14: E26424100 | I14: ET10 | J14: =IF(E14="KTG","KTG",(VLOOKUP(I14,'[1]list of outsource'!B:H,2,0))) -> UPM | K14: D000004 | M14: P000042 | N14: ET10-8.0/2.0-BK-30mm | U14: 2 | W14: Initial Submission | X14: 44044 | AE14: =LEFT(M14, FIND(" ", M14 & " ") - 1) -> P000042 | AF14: =_xlfn.XLOOKUP(AE14, Hoja2!A:A, Hoja2!A:A) -> P000042 | AG14: =LEFT(B14, FIND(" ", B14 & " ") - 1) -> PP00002-1 | AH14: =_xlfn.XLOOKUP(AG14, Hoja3!A:A, Hoja3!B:B) -> 5241 | AI14: =_xlfn.XLOOKUP(AH14, Hoja4!A:A, Hoja4!B:B) -> E26424100 | AJ14: =H14=AI14 -> TRUE
A15: =IF(X15="",(TODAY()-C15),(X15-C15)) -> 7463 | B15: PP00006-1 | C15: 38546 | D15: NO Req from Customer | E15: UPM | F15: Gentherm | G15: Hungary | H15: 11039581A | I15: ET00 | J15: =IF(E15="KTG","KTG",(VLOOKUP(I15,'[1]list of outsource'!B:H,2,0))) -> Woer | K15: D000002 | M15: P100207 | N15: ET00 SWS135-55PXV000, 19.0/9.5-Black | U15: 2 | W15: Initial Submission | AE15: =LEFT(M15, FIND(" ", M15 & " ") - 1) -> P100207 | AF15: =_xlfn.XLOOKUP(AE15, Hoja2!A:A, Hoja2!A:A) -> P100207 | AG15: =LEFT(B15, FIND(" ", B15 & " ") - 1) -> PP00006-1 | AH15: =_xlfn.XLOOKUP(AG15, Hoja3!A:A, Hoja3!B:B) -> 5234 | AI15: =_xlfn.XLOOKUP(AH15, Hoja4!A:A, Hoja4!B:B) -> 11039581A | AJ15: =H15=AI15 -> TRUE
A16: =IF(X16="",(TODAY()-C16),(X16-C16)) -> 5818 | B16: PP00007-1 | C16: 38546 | D16: Approved 2021 | E16: UPM | F16: PKC | G16: Poland | H16: GP078903 | I16: ET00 | J16: =IF(E16="KTG","KTG",(VLOOKUP(I16,'[1]list of outsource'!B:H,2,0))) -> Woer | K16: D000002 | M16: P100257 | N16: ET00 SWS135-55PXV000, 32.0/16.0-Black | U16: 2 | W16: Initial Submission | X16: 44364 | Y16: 44368 | AE16: =LEFT(M16, FIND(" ", M16 & " ") - 1) -> P100257 | AF16: =_xlfn.XLOOKUP(AE16, Hoja2!A:A, Hoja2!A:A) -> P100257 | AG16: =LEFT(B16, FIND(" ", B16 & " ") - 1) -> PP00007-1 | AH16: =_xlfn.XLOOKUP(AG16, Hoja3!A:A, Hoja3!B:B) -> 5552 | AI16: =_xlfn.XLOOKUP(AH16, Hoja4!A:A, Hoja4!B:B) -> GP078903 | AJ16: =H16=AI16 -> TRUE
A17: =IF(X17="",(TODAY()-C17),(X17-C17)) -> 5947 | B17: PP00010-1 | C17: 38546 | D17: Approved 2021 | E17: UPM | F17: Gentherm | G17: Hungary | H17: 11026984A | I17: ET52 | J17: =IF(E17="KTG","KTG",(VLOOKUP(I17,'[1]list of outsource'!B:H,2,0))) -> UPM | K17: D000043 | M17: P100262 | N17: ET52 SWS135-55PXM000, 4.8/1.6-15mm-WHT-LH | U17: 2 | W17: Initial Submission | X17: 44493 | Y17: 44502 | AE17: =LEFT(M17, FIND(" ", M17 & " ") - 1) -> P100262 | AF17: =_xlfn.XLOOKUP(AE17, Hoja2!A:A, Hoja2!A:A) -> P100262 | AG17: =LEFT(B17, FIND(" ", B17 & " ") - 1) -> PP00010-1 | AH17: =_xlfn.XLOOKUP(AG17, Hoja3!A:A, Hoja3!B:B) -> 5236 | AI17: =_xlfn.XLOOKUP(AH17, Hoja4!A:A, Hoja4!B:B) -> 11026984A | AJ17: =H17=AI17 -> TRUE
A18: =IF(X18="",(TODAY()-C18),(X18-C18)) -> 5947 | B18: PP00010-2 | C18: 38546 | D18: Approved 2021 | E18: UPM | F18: Gentherm | G18: Hungary | H18: 11026985A | I18: ET52 | J18: =IF(E18="KTG","KTG",(VLOOKUP(I18,'[1]list of outsource'!B:H,2,0))) -> UPM | K18: D000043 | M18: P100263 | N18: ET52 SWS135-55PXM000, 4.8/1.6-15mm-WHT-RH | U18: 2 | W18: Initial Submission | X18: 44493 | Y18: 44502 | AE18: =LEFT(M18, FIND(" ", M18 & " ") - 1) -> P100263 | AF18: =_xlfn.XLOOKUP(AE18, Hoja2!A:A, Hoja2!A:A) -> P100263 | AG18: =LEFT(B18, FIND(" ", B18 & " ") - 1) -> PP00010-2 | AH18: =_xlfn.XLOOKUP(AG18, Hoja3!A:A, Hoja3!B:B) -> 5238 | AI18: =_xlfn.XLOOKUP(AH18, Hoja4!A:A, Hoja4!B:B) -> 11026985A | AJ18: =H18=AI18 -> TRUE
A19: =IF(X19="",(TODAY()-C19),(X19-C19)) -> 5498 | B19: PP00002-2 | C19: 38546 | E19: UPM | F19: Lear | G19: Morocco | H19: E26459700 | I19: ET10 | J19: =IF(E19="KTG","KTG",(VLOOKUP(I19,'[1]list of outsource'!B:H,2,0))) -> UPM | K19: D000004 | M19: P000043 | N19: ET10-12.0/3.0-BLK-50mm | U19: 2 | W19: Initial Submission | X19: 44044 | AE19: =LEFT(M19, FIND(" ", M19 & " ") - 1) -> P000043 | AF19: =_xlfn.XLOOKUP(AE19, Hoja2!A:A, Hoja2!A:A) -> P000043 | AG19: =LEFT(B19, FIND(" ", B19 & " ") - 1) -> PP00002-2 | AH19: =_xlfn.XLOOKUP(AG19, Hoja3!A:A, Hoja3!B:B) -> 5243 | AI19: =_xlfn.XLOOKUP(AH19, Hoja4!A:A, Hoja4!B:B) -> E26459700 | AJ19: =H19=AI19 -> TRUE
A20: =IF(X20="",(TODAY()-C20),(X20-C20)) -> 6004 | B20: PP00011-1 | C20: 38546 | D20: PSW Pending Approve | E20: KTG | F20: Nexans | G20: Mexico | H20: 95850332 | I20: RO | J20: =IF(E20="KTG","KTG",(VLOOKUP(I20,'[1]list of outsource'!B:H,2,0))) -> KTG | K20: RO 001 | M20: E101703 | N20: CYG-DWT-RO(4005)-18.3-BK-75 | U20: 1 | W20: Tooling | X20: 44550 | AE20: =LEFT(M20, FIND(" ", M20 & " ") - 1) -> E101703 | AF20: =_xlfn.XLOOKUP(AE20, Hoja2!A:A, Hoja2!A:A) -> E101703 | AG20: =LEFT(B20, FIND(" ", B20 & " ") - 1) -> PP00011-1 | AH20: =_xlfn.XLOOKUP(AG20, Hoja3!A:A, Hoja3!B:B) -> 105 | AI20: =_xlfn.XLOOKUP(AH20, Hoja4!A:A, Hoja4!B:B) -> 95850332 | AJ20: =H20=AI20 -> TRUE
A21: =IF(X21="",(TODAY()-C21),(X21-C21)) -> 6004 | B21: PP00011-2 | C21: 38546 | D21: PSW Pending Approve | E21: KTG | F21: Nexans | G21: Mexico | H21: 95850007 | I21: RO | J21: =IF(E21="KTG","KTG",(VLOOKUP(I21,'[1]list of outsource'!B:H,2,0))) -> KTG | K21: RO 001 | M21: E101701 | N21: CYG-DWT-RO(4005)-18.3-BK-150 | U21: 1 | W21: Tooling | X21: 44550 | AE21: =LEFT(M21, FIND(" ", M21 & " ") - 1) -> E101701 | AF21: =_xlfn.XLOOKUP(AE21, Hoja2!A:A, Hoja2!A:A) -> E101701 | AG21: =LEFT(B21, FIND(" ", B21 & " ") - 1) -> PP00011-2 | AH21: =_xlfn.XLOOKUP(AG21, Hoja3!A:A, Hoja3!B:B) -> 103 | AI21: =_xlfn.XLOOKUP(AH21, Hoja4!A:A, Hoja4!B:B) -> 95850007 | AJ21: =H21=AI21 -> TRUE
A22: =IF(X22="",(TODAY()-C22),(X22-C22)) -> 6091 | B22: PP00015-1 | C22: 38546 | D22: PSW Pending Approve | E22: UPM | F22: Meissner | G22: Germany | H22: 012538 | I22: ET00 | J22: =IF(E22="KTG","KTG",(VLOOKUP(I22,'[1]list of outsource'!B:H,2,0))) -> Woer | K22: D000002 | M22: P000030 | N22: ET00 SWS135-55PXV000, 3.2/1.6-Black | U22: 1 | W22: Initial Submission | X22: 44637 | AE22: =LEFT(M22, FIND(" ", M22 & " ") - 1) -> P000030 | AF22: =_xlfn.XLOOKUP(AE22, Hoja2!A:A, Hoja2!A:A) -> P000030 | AG22: =LEFT(B22, FIND(" ", B22 & " ") - 1) -> PP00015-1 | AH22: =_xlfn.XLOOKUP(AG22, Hoja3!A:A, Hoja3!B:B) -> #N/A
A23: =IF(X23="",(TODAY()-C23),(X23-C23)) -> 5899 | B23: PP00009-1 | C23: 38546 | D23: PSW Pending Approve | E23: UPM | F23: PKC | G23: Lithuania | H23: GP085283 | I23: ET11 | J23: =IF(E23="KTG","KTG",(VLOOKUP(I23,'[1]list of outsource'!B:H,2,0))) -> UPM | K23: D00005 | M23: P000028 | N23: ET11 DWS125-55PXTEVR, 24/6-Black | U23: 2 | W23: Initial Submission | X23: 44445 | AE23: =LEFT(M23, FIND(" ", M23 & " ") - 1) -> P000028 | AF23: =_xlfn.XLOOKUP(AE23, Hoja2!A:A, Hoja2!A:A) -> P000028 | AG23: =LEFT(B23, FIND(" ", B23 & " ") - 1) -> PP00009-1 | AH23: 5558 | AI23: =_xlfn.XLOOKUP(AH23, Hoja4!A:A, Hoja4!B:B) -> GP085283 | AJ23: =H23=AI23 -> TRUE
A24: =IF(X24="",(TODAY()-C24),(X24-C24)) -> 6224 | B24: PP00014-01 | C24: 38547 | D24: Approved 2022 | E24: ETC | F24: ECI | G24: Mexico | H24: HST555P78 | I24: ET72 | J24: =IF(E24="KTG","KTG",(VLOOKUP(I24,'[1]list of outsource'!B:H,2,0))) -> Kebao | K24: D000066 | M24: P000115 | N24: ET72-9.5/4.8-38MM-BLK | U24: 2 | W24: Initial Submission | X24: 44771 | Y24: 44778 | AE24: =LEFT(M24, FIND(" ", M24 & " ") - 1) -> P000115 | AF24: =_xlfn.XLOOKUP(AE24, Hoja2!A:A, Hoja2!A:A) -> P000115 | AG24: =LEFT(B24, FIND(" ", B24 & " ") - 1) -> PP00014-01 | AH24: =_xlfn.XLOOKUP(AG24, Hoja3!A:A, Hoja3!B:B) -> 5173 | AI24: =_xlfn.XLOOKUP(AH24, Hoja4!A:A, Hoja4!B:B) -> HST555P78 | AJ24: =H24=AI24 -> TRUE
A25: =IF(X25="",(TODAY()-C25),(X25-C25)) -> 5450 | B25: PP00003-1 | C25: 38547 | D25: Approved 2020 | E25: KTG | F25: Nexans | G25: Mexico | H25: 95850329 | I25: RO | J25: =IF(E25="KTG","KTG",(VLOOKUP(I25,'[1]list of outsource'!B:H,2,0))) -> KTG | K25: RO 001 | M25: E101702 | N25: CYG-DWT-RO(4005)-5.75-BK-75 | U25: 4 | W25: Initial Submission | X25: 43997 | Y25: 44067 | AE25: =LEFT(M25, FIND(" ", M25 & " ") - 1) -> E101702 | AF25: =_xlfn.XLOOKUP(AE25, Hoja2!A:A, Hoja2!A:A) -> E101702 | AG25: =LEFT(B25, FIND(" ", B25 & " ") - 1) -> PP00003-1 | AH25: =_xlfn.XLOOKUP(AG25, Hoja3!A:A, Hoja3!B:B) -> 104 | AI25: =_xlfn.XLOOKUP(AH25, Hoja4!A:A, Hoja4!B:B) -> 95850329 | AJ25: =H25=AI25 -> TRUE
A26: =IF(X26="",(TODAY()-C26),(X26-C26)) -> 5450 | B26: PP00003-2 | C26: 38547 | D26: Approved 2020 | E26: KTG | F26: Nexans | G26: Mexico | H26: 95850330 | I26: RO | J26: =IF(E26="KTG","KTG",(VLOOKUP(I26,'[1]list of outsource'!B:H,2,0))) -> KTG | K26: RO 001 | M26: E101705 | N26: CYG-DWT-RO(4005)-7.4-BK-75 | U26: 4 | W26: Initial Submission | X26: 43997 | Y26: 44067 | AE26: =LEFT(M26, FIND(" ", M26 & " ") - 1) -> E101705 | AF26: =_xlfn.XLOOKUP(AE26, Hoja2!A:A, Hoja2!A:A) -> E101705 | AG26: =LEFT(B26, FIND(" ", B26 & " ") - 1) -> PP00003-2 | AH26: =_xlfn.XLOOKUP(AG26, Hoja3!A:A, Hoja3!B:B) -> 107 | AI26: =_xlfn.XLOOKUP(AH26, Hoja4!A:A, Hoja4!B:B) -> 95850330 | AJ26: =H26=AI26 -> TRUE
A27: =IF(X27="",(TODAY()-C27),(X27-C27)) -> 5450 | B27: PP00003-3 | C27: 38547 | D27: Approved 2020 | E27: KTG | F27: Nexans | G27: Mexico | H27: 95850331 | I27: RO | J27: =IF(E27="KTG","KTG",(VLOOKUP(I27,'[1]list of outsource'!B:H,2,0))) -> KTG | K27: RO 001 | M27: E101706 | N27: CYG-DWT-RO(4005)-11.0-BK-75 | U27: 4 | W27: Initial Submission | X27: 43997 | Y27: 44067 | AE27: =LEFT(M27, FIND(" ", M27 & " ") - 1) -> E101706 | AF27: =_xlfn.XLOOKUP(AE27, Hoja2!A:A, Hoja2!A:A) -> E101706 | AG27: =LEFT(B27, FIND(" ", B27 & " ") - 1) -> PP00003-3 | AH27: =_xlfn.XLOOKUP(AG27, Hoja3!A:A, Hoja3!B:B) -> 108 | AI27: =_xlfn.XLOOKUP(AH27, Hoja4!A:A, Hoja4!B:B) -> 95850331 | AJ27: =H27=AI27 -> TRUE
A28: =IF(X28="",(TODAY()-C28),(X28-C28)) -> 5450 | B28: PP00003-4 | C28: 38547 | D28: Approved 2020 | E28: KTG | F28: Nexans | G28: Mexico | H28: 95850332 | I28: RO | J28: =IF(E28="KTG","KTG",(VLOOKUP(I28,'[1]list of outsource'!B:H,2,0))) -> KTG | K28: RO 001 | M28: E101703 | N28: CYG-DWT-RO(4005)-18.3-BK-75 | U28: 4 | W28: Initial Submission | X28: 43997 | Y28: 44067 | AE28: =LEFT(M28, FIND(" ", M28 & " ") - 1) -> E101703 | AF28: =_xlfn.XLOOKUP(AE28, Hoja2!A:A, Hoja2!A:A) -> E101703 | AG28: =LEFT(B28, FIND(" ", B28 & " ") - 1) -> PP00003-4 | AH28: =_xlfn.XLOOKUP(AG28, Hoja3!A:A, Hoja3!B:B) -> 105 | AI28: =_xlfn.XLOOKUP(AH28, Hoja4!A:A, Hoja4!B:B) -> 95850332 | AJ28: =H28=AI28 -> TRUE
A29: =IF(X29="",(TODAY()-C29),(X29-C29)) -> 5450 | B29: PP00003-5 | C29: 38547 | D29: Approved 2020 | E29: KTG | F29: Nexans | G29: Mexico | H29: 95850007 | I29: RO | J29: =IF(E29="KTG","KTG",(VLOOKUP(I29,'[1]list of outsource'!B:H,2,0))) -> KTG | K29: RO 001 | M29: E101701 | N29: CYG-DWT-RO(4005)-18.3-BK-150 | U29: 4 | W29: Initial Submission | X29: 43997 | Y29: 44067 | AE29: =LEFT(M29, FIND(" ", M29 & " ") - 1) -> E101701 | AF29: =_xlfn.XLOOKUP(AE29, Hoja2!A:A, Hoja2!A:A) -> E101701 | AG29: =LEFT(B29, FIND(" ", B29 & " ") - 1) -> PP00003-5 | AH29: =_xlfn.XLOOKUP(AG29, Hoja3!A:A, Hoja3!B:B) -> 103 | AI29: =_xlfn.XLOOKUP(AH29, Hoja4!A:A, Hoja4!B:B) -> 95850007 | AJ29: =H29=AI29 -> TRUE
A30: =IF(X30="",(TODAY()-C30),(X30-C30)) -> 5817 | B30: PP00007-1 | C30: 38547 | D30: Approved 2021 | E30: UPM | F30: PKC | G30: Poland | H30: GP078903 | I30: ET00 | J30: =IF(E30="KTG","KTG",(VLOOKUP(I30,'[1]list of outsource'!B:H,2,0))) -> Woer | K30: D000002 | M30: P100257 | N30: ET00 SWS135-55PXV000, 32.0/16.0-Black | U30: 2 | W30: Initial Submission | X30: 44364 | Y30: 44368 | AE30: =LEFT(M30, FIND(" ", M30 & " ") - 1) -> P100257 | AF30: =_xlfn.XLOOKUP(AE30, Hoja2!A:A, Hoja2!A:A) -> P100257 | AG30: =LEFT(B30, FIND(" ", B30 & " ") - 1) -> PP00007-1 | AH30: =_xlfn.XLOOKUP(AG30, Hoja3!A:A, Hoja3!B:B) -> 5552 | AI30: =_xlfn.XLOOKUP(AH30, Hoja4!A:A, Hoja4!B:B) -> GP078903 | AJ30: =H30=AI30 -> TRUE
A31: =IF(X31="",(TODAY()-C31),(X31-C31)) -> 5497 | B31: PP00002-1 | C31: 38547 | E31: UPM | F31: Lear | G31: Morocco | H31: E26424100 | I31: ET10 | J31: =IF(E31="KTG","KTG",(VLOOKUP(I31,'[1]list of outsource'!B:H,2,0))) -> UPM | K31: D000004 | M31: P000042 | N31: ET10-8.0/2.0-BK-30mm | U31: 2 | W31: Initial Submission | X31: 44044 | AE31: =LEFT(M31, FIND(" ", M31 & " ") - 1) -> P000042 | AF31: =_xlfn.XLOOKUP(AE31, Hoja2!A:A, Hoja2!A:A) -> P000042 | AG31: =LEFT(B31, FIND(" ", B31 & " ") - 1) -> PP00002-1 | AH31: =_xlfn.XLOOKUP(AG31, Hoja3!A:A, Hoja3!B:B) -> 5241 | AI31: =_xlfn.XLOOKUP(AH31, Hoja4!A:A, Hoja4!B:B) -> E26424100 | AJ31: =H31=AI31 -> TRUE
A32: =IF(X32="",(TODAY()-C32),(X32-C32)) -> 5589 | B32: PP00001-1 | C32: 38547 | D32: Program died | E32: KTG | F32: Gentherm | G32: Mexico | H32: 18052000A | I32: ET36 | J32: =IF(E32="KTG","KTG",(VLOOKUP(I32,'[1]list of outsource'!B:H,2,0))) -> KTG | K32: D000017 | M32: P000035 | N32: ET36 SWN090-40PVV000, 4.6-800m Black | U32: 2 | X32: 44136 | AE32: =LEFT(M32, FIND(" ", M32 & " ") - 1) -> P000035 | AF32: =_xlfn.XLOOKUP(AE32, Hoja2!A:A, Hoja2!A:A) -> #N/A
A33: =IF(X33="",(TODAY()-C33),(X33-C33)) -> 5589 | B33: PP00001-2 | C33: 38547 | D33: Program died | E33: KTG | F33: Gentherm | G33: Mexico | H33: 18052001A | I33: ET36 | J33: =IF(E33="KTG","KTG",(VLOOKUP(I33,'[1]list of outsource'!B:H,2,0))) -> KTG | K33: D000017 | M33: P000036 | N33: ET36 SWN090-40PVV000, 5.1-500m Black | U33: 2 | X33: 44136 | AE33: =LEFT(M33, FIND(" ", M33 & " ") - 1) -> P000036 | AF33: =_xlfn.XLOOKUP(AE33, Hoja2!A:A, Hoja2!A:A) -> #N/A
A34: =IF(X34="",(TODAY()-C34),(X34-C34)) -> 5589 | B34: PP00001-3 | C34: 38547 | D34: Program died | E34: KTG | F34: Gentherm | G34: Mexico | H34: 12000051A | I34: ET36 | J34: =IF(E34="KTG","KTG",(VLOOKUP(I34,'[1]list of outsource'!B:H,2,0))) -> KTG | K34: D000017 | M34: P000037 | N34: ET36 SWN090-40PVV000, 6.0-400m Black | U34: 2 | X34: 44136 | AE34: =LEFT(M34, FIND(" ", M34 & " ") - 1) -> P000037 | AF34: =_xlfn.XLOOKUP(AE34, Hoja2!A:A, Hoja2!A:A) -> #N/A
A35: =IF(X35="",(TODAY()-C35),(X35-C35)) -> 5589 | B35: PP00001-4 | C35: 38547 | D35: Program died | E35: KTG | F35: Gentherm | G35: Mexico | H35: 18052002A | I35: ET36 | J35: =IF(E35="KTG","KTG",(VLOOKUP(I35,'[1]list of outsource'!B:H,2,0))) -> KTG | K35: D000017 | M35: P000038 | N35: ET36 SWN090-40PVV000, 6.1-500m Black | U35: 2 | X35: 44136 | AE35: =LEFT(M35, FIND(" ", M35 & " ") - 1) -> P000038 | AF35: =_xlfn.XLOOKUP(AE35, Hoja2!A:A, Hoja2!A:A) -> #N/A
A36: =IF(X36="",(TODAY()-C36),(X36-C36)) -> 5589 | B36: PP00001-5 | C36: 38547 | D36: Program died | E36: KTG | F36: Gentherm | G36: Mexico | H36: 12002514A | I36: ET36 | J36: =IF(E36="KTG","KTG",(VLOOKUP(I36,'[1]list of outsource'!B:H,2,0))) -> KTG | K36: D000017 | M36: P000040 | N36: ET36 SWN090-40PVV000,7.0-340m Black | U36: 2 | X36: 44136 | AE36: =LEFT(M36, FIND(" ", M36 & " ") - 1) -> P000040 | AF36: =_xlfn.XLOOKUP(AE36, Hoja2!A:A, Hoja2!A:A) -> #N/A
A37: =IF(X37="",(TODAY()-C37),(X37-C37)) -> 5589 | B37: PP00001-6 | C37: 38547 | D37: Program died | E37: KTG | F37: Gentherm | G37: Mexico | H37: 18052065A | I37: ET36 | J37: =IF(E37="KTG","KTG",(VLOOKUP(I37,'[1]list of outsource'!B:H,2,0))) -> KTG | K37: D000017 | M37: P000039 | N37: ET36 SWN090-40PVV000,7.1-350m Black | U37: 2 | X37: 44136 | AE37: =LEFT(M37, FIND(" ", M37 & " ") - 1) -> P000039 | AF37: =_xlfn.XLOOKUP(AE37, Hoja2!A:A, Hoja2!A:A) -> #N/A
A38: =IF(X38="",(TODAY()-C38),(X38-C38)) -> 5589 | B38: PP00001-7 | C38: 38547 | D38: Program died | E38: KTG | F38: Gentherm | G38: Mexico | H38: 12001469A | I38: ET36 | J38: =IF(E38="KTG","KTG",(VLOOKUP(I38,'[1]list of outsource'!B:H,2,0))) -> KTG | K38: D000017 | M38: P000041 | N38: ET36 SWN090-40PVV000, 10.0-150m Black | U38: 2 | X38: 44136 | AE38: =LEFT(M38, FIND(" ", M38 & " ") - 1) -> P000041 | AF38: =_xlfn.XLOOKUP(AE38, Hoja2!A:A, Hoja2!A:A) -> #N/A
A39: =IF(X39="",(TODAY()-C39),(X39-C39)) -> 5497 | B39: PP00002-2 | C39: 38547 | E39: UPM | F39: Lear | G39: Morocco | H39: E26459700 | I39: ET10 | J39: =IF(E39="KTG","KTG",(VLOOKUP(I39,'[1]list of outsource'!B:H,2,0))) -> UPM | K39: D000004 | M39: P000043 | N39: ET10-12.0/3.0-BLK-50mm | U39: 2 | W39: Initial Submission | X39: 44044 | AE39: =LEFT(M39, FIND(" ", M39 & " ") - 1) -> P000043 | AF39: =_xlfn.XLOOKUP(AE39, Hoja2!A:A, Hoja2!A:A) -> P000043 | AG39: =LEFT(B39, FIND(" ", B39 & " ") - 1) -> PP00002-2 | AH39: =_xlfn.XLOOKUP(AG39, Hoja3!A:A, Hoja3!B:B) -> 5243 | AI39: =_xlfn.XLOOKUP(AH39, Hoja4!A:A, Hoja4!B:B) -> E26459700 | AJ39: =H39=AI39 -> TRUE
A40: =IF(X40="",(TODAY()-C40),(X40-C40)) -> 7462 | B40: PP00006-1 | C40: 38547 | D40: NO Req from Customer | E40: KTG | F40: Gentherm | G40: Hungary | H40: 11039581A | I40: ET00 | J40: =IF(E40="KTG","KTG",(VLOOKUP(I40,'[1]list of outsource'!B:H,2,0))) -> KTG | K40: D000002 | M40: P100207 | N40: ET00 SWS135-55PXV000, 19.0/9.5-Black | U40: 2 | W40: Initial Submission | AE40: =LEFT(M40, FIND(" ", M40 & " ") - 1) -> P100207 | AF40: =_xlfn.XLOOKUP(AE40, Hoja2!A:A, Hoja2!A:A) -> P100207 | AG40: =LEFT(B40, FIND(" ", B40 & " ") - 1) -> PP00006-1 | AH40: =_xlfn.XLOOKUP(AG40, Hoja3!A:A, Hoja3!B:B) -> 5234 | AI40: =_xlfn.XLOOKUP(AH40, Hoja4!A:A, Hoja4!B:B) -> 11039581A | AJ40: =H40=AI40 -> TRUE
...

Sheet Hoja2
A1: 1230ES-19-25-SLV
A2: 1230ES-9-25-SLV
A3: 1238X-19-25-SLV
A4: 1238X-25-25-SLV
A5: 1238XLT1-180-50-SIL
A6: 1239X-19-25-SLV
A7: 1239X-25-25-SLV
A8: 1239X-30-25-SLV
A9: 1239X-32-25-SLV
A10: 1288X-19-25-SLV
A11: 1288X-25-25-BLK
A12: 1288X-32-25-SLV
... A1289: P500063

Sheet Hoja3
A1: PP00003-1 | B1: 104
A2: PP00003-2 | B2: 107
A3: PP00003-3 | B3: 108
A4: PP00003-4 | B4: 105
A5: PP00003-5 | B5: 103
A6: PP00007-1 | B6: 5552
A7: PP00008-01 | B7: 5554
A8: PP00008-01 | B8: 5554
A9: PP00008-02 | B9: 5556
A10: PP00008-02 | B10: 5556
A11: PP00010-1 | B11: 5236
A12: PP00010-2 | B12: 5238
... A1002: PP00028-0063 | B1002: 5300

Sheet Hoja4
A1: 2 | B1: M1185 | C1: 2 | D1: 512-19-25-BLK
A2: 3 | B2: M1372-BE | C2: 2 | D2: 651MSX-19-33-BLU
A3: 4 | B3: M1547 | C3: 2 | D3: 832MPXRT-35-10-BLK-RT
A4: 5 | B4: M1514 | C4: 2 | D4: 833MPX-38-5-BLK
A5: 6 | B5: M0802 | C5: 2 | D5: 8375X-19-25-BLK
A6: 7 | B6: M1317 | C6: 2 | D6: 837X-19-25-BLK
A7: 8 | B7: M1517 | C7: 2 | D7: 837X-38-25-BLK
A8: 9 | B8: M1212 | C8: 2 | D8: 839X-19-25-BLK
A9: 10 | B9: M1528 | C9: 2 | D9: 8550X-19-25-BLK
A10: 11 | B10: M1502 | C10: 2 | D10: 8550X-25-25-BLK
A11: 12 | B11: 505-19-25-BLK | C11: 3 | D11: 505-19-25-BLK
A12: 13 | B12: 505-25 | C12: 3 | D12: 505-25-25-BLK
... A74: 78 | B74: 8550-25-25-BLK | C74: 91 | D74: 8550-25-25-BLK
A75: 80 | B75: 252366 | C75: 98 | D75: P000336
A76: 81 | B76: 252367 | C76: 98 | D76: P000337
A77: 82 | B77: 249390 | C77: 98 | D77: P000341
A78: 83 | B78: TBD | C78: 98 | D78: P200249
A79: 84 | B79: 317-19-33-BLK | C79: 102 | D79: 317-19-33-BLK
A80: 85 | B80: 8310SE-19-25-BLK | C80: 102 | D80: 8310SE-19-25-BLK
A81: 86 | B81: 8375X-19-25-BLK | C81: 102 | D81: 8375X-19-25-BLK
A82: 87 | B82: 837X-19-25-BLK | C82: 102 | D82: 837X-19-25-BLK
A83: 88 | B83: 837X-25-25-BLK | C83: 102 | D83: 837X-25-25-BLK
A84: 89 | B84: 837X-9-25-BLK | C84: 102 | D84: 837X-9-25-BLK
A85: 90 | B85: G141043 | C85: 105 | D85: 837X-19-25-BLK
A86: 91 | B86: 615810001 | C86: 254 | D86: 837X-9-25-BLK
A87: 92 | B87: 837X | C87: 236 | D87: 837X-19-25-BLK
A88: 93 | B88: 651MSX-19-33-BLK | C88: 237 | D88: 651MSX-19-33-BLK
A89: 94 | B89: 839-19-25-BLK | C89: 237 | D89: 839-19-25-BLK
A90: 95 | B90: 839X-9-25-BLK | C90: 237 | D90: 839X-9-25-BLK
A91: 96 | B91: 8550X-19-25 | C91: 237 | D91: 8550X-19-25-BLK
A92: 97 | B92: 2509328C1 | C92: 242 | D92: 8575X-25-5-BLK
A93: 100 | B93: 95819518 | C93: 243 | D93: 832MPX-19-15-BLK
A94: 103 | B94: 95850007 | C94: 243 | D94: E101701
A95: 104 | B95: 95850329 | C95: 243 | D95: E101702
A96: 105 | B96: 95850332 | C96: 243 | D96: E101703
A97: 107 | B97: 95850330 | C97: 243 | D97: E101705
A98: 108 | B98: 95850331 | C98: 243 | D98: E101706
A99: 109 | B99: 95890015 | C99: 243 | D99: E101707
A100: 110 | B100: 95850340 | C100: 243 | D100: E101709
A101: 111 | B101: 95850698 | C101: 243 | D101: E101710
...
